Workbook

Sheet Eingaben
A1: INEKON | Auslegung Trinkwarmwasser-Speicher (TWW) — Version 2.1.2
A2: Eingabeblatt — bitte nur die gelb hinterlegten Zellen (blaue Schrift) ausfüllen. Schwarze Zellen sind Formeln, grüne Zellen verweisen auf andere Blätter.
A4: 1 Projektdaten
A5: Objektname | B5: Musterprojekt Beispielstraße 1
A6: Bearbeiter | B6: INEKON
A7: Datum | B7: 46232
A9: 2 Gebäude / Nutzung
A10: Nutzungstyp | B10: Büro/Verwaltung | D10: Auswahl steuert Richtwert und Standard-Zapfprofil
A11: Anzahl Einheiten | B11: 60 | C11: WE / Zimmer / Betten / Pers. | D11: neutrale Bezugsgröße je nach Nutzungstyp
A12: Personen je Einheit | B12: 2.2 | C12: P/Einheit | D12: mittlere Belegung
A13: Personen gesamt | B13: =B11*B12 -> 132 | C13: P | D13: = Einheiten × Personen je Einheit
A15: 3 Warmwasserbedarf
A16: Bedarfsermittlung | B16: auto | C16: auto / manuell | D16: 'auto' übernimmt den Richtwert aus der Tabelle unten
A17: Richtwert lt. Tabelle | B17: =IFERROR(INDEX($D$36:$D$46,MATCH($B$10,$A$36:$A$46,0)),0) -> 17.6 | C17: l/(Einheit·d) | D17: Nachschlag über Nutzungstyp, auf die Einheit umgerechnet
A18: Manueller Wert | B18: 77 | C18: l/(Einheit·d) | D18: wirkt nur bei Bedarfsermittlung = 'manuell'
A19: Angesetzter spez. Tagesbedarf | B19: =IF($B$16="auto",$B$17,$B$18) -> 17.6 | C19: l/(Einheit·d) | D19: maßgebender Wert für alle Berechnungen (bei 60 °C)
A21: 4 Temperaturen
A22: Speichertemperatur T_Speicher | B22: 60 | C22: °C | D22: Sollwert Speicheraustritt (DVGW W 551: ≥ 60 °C)
A23: Kaltwassertemperatur T_KW | B23: 10 | C23: °C | D23: Jahresmittel Trinkwasser kalt
A24: Zapftemperatur (informativ) | B24: 45 | C24: °C | D24: nur informativ — geht nicht in die Rechnung ein
A25: nutzbare Spreizung ΔT | B25: =B22-B23 -> 50 | C25: K | D25: = T_Speicher − T_KW
A27: 5 Anlagentechnik / Sicherheiten
A28: WP-Ladeleistung P_lade (TWW-Betrieb) | B28: 4 | C28: kW | D28: konstante Ladeleistung im Bilanzmodell — Wert aus Abschnitt 8 (Schätzhilfe) | E28: Umschalter und Rechenweg siehe Abschnitt 8 (Zeilen 62–68)
A29: Zirkulationsverlust | B29: 0.2 | C29: kW | D29: Dauerlast rund um die Uhr; 0 = ohne Zirkulation — Wert aus Abschnitt 9 | E29: Methodenwahl und Rechenweg siehe Abschnitt 9 (Zeilen 72–80)
A30: nutzbarer Speicheranteil f_nutz | B30: 0.8 | C30: – | D30: Schichtung / Totvolumen; üblich 0,7 … 0,85
A31: Sicherheitszuschlag | B31: 0.15 | C31: – | D31: Bereitschafts-/Sicherheitszuschlag auf das Volumen (0,15 = 15 %) | E31: 10–20 %; VDI 6002: Einzeltages-Stundenspitzen bis ~2× Profilwert — bei kleinen Anlagen eher 20 %
A33: 6 Richtwerte spezifischer Warmwasserbedarf (anpassbar)
A34: Quelle: Zeilen 36–42 Richtwerte in Anlehnung an DIN V 18599-10 / VDI-Praxis. Zeilen 43–46 aus VDI 6002 Blatt 1 Anhang D bzw. VDI 6002 Blatt 2 Tabellen 2/4/5 (Jahresmittelwerte). Alle Werte beziehen sich auf 60 °C.
A35: Nutzungstyp | B35: Richtwert | C35: Bezug | D35: je Einheit·d (berechnet) | E35: Bemerkung
A36: MFH Wohnen | B36: 35 | C36: Person | D36: =IF($C36="Person",$B36*$B$12,$B36) -> 77 | E36: Mehrfamilienhaus, Bad + Küche, 30–45 l/(P·d)
A37: EFH Wohnen | B37: 35 | C37: Person | D37: =IF($C37="Person",$B37*$B$12,$B37) -> 77 | E37: Ein-/Zweifamilienhaus, 30–45 l/(P·d)
A38: Hotel | B38: 60 | C38: Einheit | D38: =IF($C38="Person",$B38*$B$12,$B38) -> 60 | E38: je Zimmer/Nacht, mittlere Kategorie, 40–100 l/(Zi·d)
A39: Pflegeheim | B39: 50 | C39: Einheit | D39: =IF($C39="Person",$B39*$B$12,$B39) -> 50 | E39: je Bett, inkl. Pflegebäder, 40–70 l/(Bett·d)
A40: Büro/Verwaltung | B40: 8 | C40: Person | D40: =IF($C40="Person",$B40*$B$12,$B40) -> 17.6 | E40: Handwaschbecken, ohne Duschen, 5–12 l/(P·d)
A41: Sportstätte/Duschen | B41: 30 | C41: Person | D41: =IF($C41="Person",$B41*$B$12,$B41) -> 66 | E41: je Duschender, 25–45 l/(P·d)
A42: Schule | B42: 5 | C42: Person | D42: =IF($C42="Person",$B42*$B$12,$B42) -> 11 | E42: ohne Duschen; mit Sporthalle deutlich höher
A43: Wohnen groß (VDI 6002) | B43: 28 | C43: Person | D43: =IF($C43="Person",$B43*$B$12,$B43) -> 61.6 | E43: VDI 6002 Bl. 1 Anh. D (ZfS/Solarthermie-2000): Mittel 28, Februar-Maximum 32, Schwachlast 22 l/(P·d) @ 60 °C
A44: Studentenwohnheim (VDI 6002-2) | B44: 37 | C44: Einheit | D44: =IF($C44="Person",$B44*$B$12,$B44) -> 37 | E44: VDI 6002 Bl. 2 Tab. 2, je Vollbelegungsperson: Jahresmittel 34–45 (37); Winterspitze 45–55; Auslegung Sommerschwachlast 20 l/(vp·d)
A45: Seniorenheim (VDI 6002-2) | B45: 36 | C45: Einheit | D45: =IF($C45="Person",$B45*$B$12,$B45) -> 36 | E45: VDI 6002 Bl. 2 Tab. 4, je Bett: Jahresmittel 34–50 (36); Winterspitze 38–53; Auslegung Sommerschwachlast 33 l/(vp·d)
A46: Krankenhaus (VDI 6002-2) | B46: 38 | C46: Einheit | D46: =IF($C46="Person",$B46*$B$12,$B46) -> 38 | E46: VDI 6002 Bl. 2 Tab. 5, je Bett: Jahresmittel 35–55 (38); Winterspitze 40–60; Auslegung Sommerschwachlast 33 l/(vp·d)
...

Sheet Zapfprofil
A1: Zapfprofile — drei Tagtypen je Nutzungstyp (Version 2.1.2)
A2: Profilbibliothek (Richtwerte, anpassbar). Jede Tagtyp-Spalte muss in der Summe 100 % ergeben. Die Spalten "Benutzerdefiniert" sind frei editierbar.
A4: 1 Profilauswahl, Saisonfaktor und Kontrollen
A5: Profilauswahl (Dropdown) | B5: (automatisch) | D5: '(automatisch)' folgt dem Nutzungstyp aus 'Eingaben'
A6: Nutzungstyp lt. Blatt 'Eingaben' | B6: =Eingaben!B10 -> Büro/Verwaltung
A7: verwendetes Profil | B7: =IF($B$5="(automatisch)",$B$6,$B$5) -> Büro/Verwaltung | D7: steuert die Spalten 'Aktives Profil'
A8: Saisonfaktor (Eingabe) | B8: 1 | C8: – | D8: Default 1,0. Hinweis: Februar-Maximum Wohnen = 1,14 nach VDI 6002 Bild D1 (32 statt 28 l/(P·d)); Schwachlast ≈ 0,79.
A9: Spaltenindex Bibliothek (Hilfsgröße) | B9: =(MATCH($B$7,$A$49:$A$60,0)-1)*3+1 -> 25 | D9: Position der ersten Spalte des gewählten Nutzungstyps im Block B:AK
A10: Summenkontrolle Tagesprofil Werktag | B10: =SUM($AL$19:$AL$42) -> 1 | C10: =IF(ABS($B$10-1)>0.005,"WARNUNG: Summe ≠ 100 % — korrigieren!","OK — summiert zu 100 %.") -> OK — summiert zu 100 %. | D10: muss 100,0 % ergeben
A11: Summenkontrolle Tagesprofil Samstag | B11: =SUM($AM$19:$AM$42) -> 1 | C11: =IF(ABS($B$11-1)>0.005,"WARNUNG: Summe ≠ 100 % — korrigieren!","OK — summiert zu 100 %.") -> OK — summiert zu 100 %. | D11: muss 100,0 % ergeben
A12: Summenkontrolle Tagesprofil Sonntag | B12: =SUM($AN$19:$AN$42) -> 1 | C12: =IF(ABS($B$12-1)>0.005,"WARNUNG: Summe ≠ 100 % — korrigieren!","OK — summiert zu 100 %.") -> OK — summiert zu 100 %. | D12: muss 100,0 % ergeben
A13: Summenkontrolle Wochenfaktoren | B13: =SUM($B$61:$H$61) -> 1 | C13: =IF(ABS($B$13-1)>0.005,"WARNUNG: Summe ≠ 100 % — korrigieren!","OK — summiert zu 100 %.") -> OK — summiert zu 100 %. | D13: muss 100,0 % ergeben
A16: 2 Profilbibliothek — Anteil des Tagesbedarfs je Stunde (Werktag / Samstag / Sonntag je Nutzungstyp)
A17: Nutzungstyp → | B17: Wohnen groß (VDI 6002) | E17: Studentenwohnheim (VDI 6002-2) | H17: Seniorenheim (VDI 6002-2) | K17: Krankenhaus (VDI 6002-2) | N17: MFH Wohnen | Q17: EFH Wohnen | T17: Hotel | W17: Pflegeheim | Z17: Büro/Verwaltung | AC17: Sportstätte/Duschen | AF17: Schule | AI17: Benutzerdefiniert | AL17: Aktives Profil
A18: Stunde | B18: Werktag | C18: Samstag | D18: Sonntag | E18: Werktag | F18: Samstag | G18: Sonntag | H18: Werktag | I18: Samstag | J18: Sonntag | K18: Werktag | L18: Samstag | M18: Sonntag | N18: Werktag | O18: Samstag | P18: Sonntag | Q18: Werktag | R18: Samstag | S18: Sonntag | T18: Werktag | U18: Samstag | V18: Sonntag | W18: Werktag | X18: Samstag | Y18: Sonntag | Z18: Werktag | AA18: Samstag | AB18: Sonntag | AC18: Werktag | AD18: Samstag | AE18: Sonntag | AF18: Werktag | AG18: Samstag | AH18: Sonntag | AI18: Werktag | AJ18: Samstag | AK18: Sonntag | AL18: Werktag | AM18: Samstag | AN18: Sonntag
A19: 0 | B19: 0.016 | C19: 0.017 | D19: 0.019019019 | E19: 0.012 | F19: 0.02 | G19: 0.013 | H19: 0.003 | I19: 0.004 | J19: 0.004 | K19: 0.004 | L19: 0.004 | M19: 0.004 | N19: 0.005 | O19: 0.007 | P19: 0.008 | Q19: 0.004 | R19: 0.006 | S19: 0.007 | T19: 0.005 | U19: 0.006 | V19: 0.007 | W19: 0.005 | X19: 0.006 | Y19: 0.006 | Z19: 0 | AA19: 0.02 | AB19: 0.02 | AC19: 0 | AD19: 0 | AE19: 0 | AF19: 0 | AG19: 0 | AH19: 0 | AI19: 0.005 | AJ19: 0.007 | AK19: 0.008 | AL19: =INDEX($B19:$AK19,$B$9+0) -> 0 | AM19: =INDEX($B19:$AK19,$B$9+1) -> 0.02 | AN19: =INDEX($B19:$AK19,$B$9+2) -> 0.02
A20: 1 | B20: 0.008 | C20: 0.011 | D20: 0.012012012 | E20: 0.009 | F20: 0.007 | G20: 0.012 | H20: 0.003 | I20: 0.004 | J20: 0.004 | K20: 0.004 | L20: 0.004 | M20: 0.004 | N20: 0.005 | O20: 0.006 | P20: 0.007 | Q20: 0.003 | R20: 0.005 | S20: 0.006 | T20: 0.003 | U20: 0.004 | V20: 0.005 | W20: 0.005 | X20: 0.006 | Y20: 0.006 | Z20: 0 | AA20: 0.02 | AB20: 0.02 | AC20: 0 | AD20: 0 | AE20: 0 | AF20: 0 | AG20: 0 | AH20: 0 | AI20: 0.005 | AJ20: 0.006 | AK20: 0.007 | AL20: =INDEX($B20:$AK20,$B$9+0) -> 0 | AM20: =INDEX($B20:$AK20,$B$9+1) -> 0.02 | AN20: =INDEX($B20:$AK20,$B$9+2) -> 0.02
A21: 2 | B21: 0.003 | C21: 0.005 | D21: 0.007007007 | E21: 0.004 | F21: 0.003 | G21: 0.007 | H21: 0.004 | I21: 0.005 | J21: 0.005 | K21: 0.005 | L21: 0.005 | M21: 0.005 | N21: 0.005 | O21: 0.005 | P21: 0.005 | Q21: 0.003 | R21: 0.004 | S21: 0.004 | T21: 0.002 | U21: 0.003 | V21: 0.003 | W21: 0.005 | X21: 0.006 | Y21: 0.006 | Z21: 0 | AA21: 0.02 | AB21: 0.02 | AC21: 0 | AD21: 0 | AE21: 0 | AF21: 0 | AG21: 0 | AH21: 0 | AI21: 0.005 | AJ21: 0.005 | AK21: 0.005 | AL21: =INDEX($B21:$AK21,$B$9+0) -> 0 | AM21: =INDEX($B21:$AK21,$B$9+1) -> 0.02 | AN21: =INDEX($B21:$AK21,$B$9+2) -> 0.02
A22: 3 | B22: 0.003 | C22: 0.003 | D22: 0.004004004 | E22: 0.006 | F22: 0.007 | G22: 0.005 | H22: 0.006 | I22: 0.008 | J22: 0.008 | K22: 0.008 | L22: 0.008 | M22: 0.008 | N22: 0.005 | O22: 0.005 | P22: 0.005 | Q22: 0.003 | R22: 0.003 | S22: 0.003 | T22: 0.002 | U22: 0.002 | V22: 0.002 | W22: 0.005 | X22: 0.006 | Y22: 0.006 | Z22: 0 | AA22: 0.02 | AB22: 0.02 | AC22: 0 | AD22: 0 | AE22: 0 | AF22: 0 | AG22: 0 | AH22: 0 | AI22: 0.005 | AJ22: 0.005 | AK22: 0.005 | AL22: =INDEX($B22:$AK22,$B$9+0) -> 0 | AM22: =INDEX($B22:$AK22,$B$9+1) -> 0.02 | AN22: =INDEX($B22:$AK22,$B$9+2) -> 0.02
A23: 4 | B23: 0.008 | C23: 0.006 | D23: 0.004004004 | E23: 0.014 | F23: 0.013 | G23: 0.006 | H23: 0.009 | I23: 0.012 | J23: 0.012 | K23: 0.012 | L23: 0.012 | M23: 0.012 | N23: 0.01 | O23: 0.007 | P23: 0.005 | Q23: 0.007 | R23: 0.005 | S23: 0.004 | T23: 0.005 | U23: 0.004 | V23: 0.004 | W23: 0.01 | X23: 0.01 | Y23: 0.01 | Z23: 0 | AA23: 0.02 | AB23: 0.02 | AC23: 0 | AD23: 0 | AE23: 0 | AF23: 0 | AG23: 0 | AH23: 0 | AI23: 0.01 | AJ23: 0.007 | AK23: 0.005 | AL23: =INDEX($B23:$AK23,$B$9+0) -> 0 | AM23: =INDEX($B23:$AK23,$B$9+1) -> 0.02 | AN23: =INDEX($B23:$AK23,$B$9+2) -> 0.02
A24: 5 | B24: 0.025 | C24: 0.007 | D24: 0.004004004 | E24: 0.042 | F24: 0.025 | G24: 0.007 | H24: 0.017 | I24: 0.022 | J24: 0.022 | K24: 0.028 | L24: 0.028 | M24: 0.028 | N24: 0.025 | O24: 0.012 | P24: 0.008 | Q24: 0.02 | R24: 0.01 | S24: 0.007 | T24: 0.02 | U24: 0.012 | V24: 0.01 | W24: 0.03 | X24: 0.022 | Y24: 0.022 | Z24: 0 | AA24: 0.02 | AB24: 0.02 | AC24: 0 | AD24: 0.005 | AE24: 0 | AF24: 0 | AG24: 0 | AH24: 0 | AI24: 0.025 | AJ24: 0.012 | AK24: 0.008 | AL24: =INDEX($B24:$AK24,$B$9+0) -> 0 | AM24: =INDEX($B24:$AK24,$B$9+1) -> 0.02 | AN24: =INDEX($B24:$AK24,$B$9+2) -> 0.02
A25: 6 | B25: 0.073 | C25: 0.01 | D25: 0.005005005 | E25: 0.073 | F25: 0.038 | G25: 0.012 | H25: 0.1 | I25: 0.075 | J25: 0.075 | K25: 0.075 | L25: 0.075 | M25: 0.075 | N25: 0.06 | O25: 0.025 | P25: 0.015 | Q25: 0.07 | R25: 0.02 | S25: 0.015 | T25: 0.07 | U25: 0.04 | V25: 0.03 | W25: 0.08 | X25: 0.06 | Y25: 0.06 | Z25: 0.02 | AA25: 0.03 | AB25: 0.03 | AC25: 0.01 | AD25: 0.015 | AE25: 0.01 | AF25: 0 | AG25: 0 | AH25: 0 | AI25: 0.06 | AJ25: 0.025 | AK25: 0.015 | AL25: =INDEX($B25:$AK25,$B$9+0) -> 0.02 | AM25: =INDEX($B25:$AK25,$B$9+1) -> 0.03 | AN25: =INDEX($B25:$AK25,$B$9+2) -> 0.03
A26: 7 | B26: 0.077 | C26: 0.022 | D26: 0.01001001 | E26: 0.066 | F26: 0.046 | G26: 0.038 | H26: 0.17 | I26: 0.125 | J26: 0.125 | K26: 0.105 | L26: 0.105 | M26: 0.105 | N26: 0.09 | O26: 0.045 | P26: 0.03 | Q26: 0.11 | R26: 0.04 | S26: 0.03 | T26: 0.13 | U26: 0.09 | V26: 0.075 | W26: 0.11 | X26: 0.085 | Y26: 0.085 | Z26: 0.06 | AA26: 0.04 | AB26: 0.04 | AC26: 0.03 | AD26: 0.03 | AE26: 0.025 | AF26: 0.05 | AG26: 0.02 | AH26: 0.02 | AI26: 0.09 | AJ26: 0.045 | AK26: 0.03 | AL26: =INDEX($B26:$AK26,$B$9+0) -> 0.06 | AM26: =INDEX($B26:$AK26,$B$9+1) -> 0.04 | AN26: =INDEX($B26:$AK26,$B$9+2) -> 0.04
A27: 8 | B27: 0.065 | C27: 0.051 | D27: 0.035035035 | E27: 0.063 | F27: 0.078 | G27: 0.05 | H27: 0.08 | I27: 0.083 | J27: 0.083 | K27: 0.08 | L27: 0.08 | M27: 0.08 | N27: 0.08 | O27: 0.07 | P27: 0.055 | Q27: 0.075 | R27: 0.075 | S27: 0.06 | T27: 0.14 | U27: 0.135 | V27: 0.13 | W27: 0.1 | X27: 0.09 | Y27: 0.09 | Z27: 0.08 | AA27: 0.05 | AB27: 0.05 | AC27: 0.03 | AD27: 0.05 | AE27: 0.05 | AF27: 0.1 | AG27: 0.05 | AH27: 0.05 | AI27: 0.08 | AJ27: 0.07 | AK27: 0.055 | AL27: =INDEX($B27:$AK27,$B$9+0) -> 0.08 | AM27: =INDEX($B27:$AK27,$B$9+1) -> 0.05 | AN27: =INDEX($B27:$AK27,$B$9+2) -> 0.05
A28: 9 | B28: 0.053 | C28: 0.091 | D28: 0.07007007 | E28: 0.05 | F28: 0.069 | G28: 0.058 | H28: 0.075 | I28: 0.075 | J28: 0.075 | K28: 0.075 | L28: 0.075 | M28: 0.075 | N28: 0.055 | O28: 0.085 | P28: 0.08 | Q28: 0.045 | R28: 0.095 | S28: 0.09 | T28: 0.09 | U28: 0.11 | V28: 0.12 | W28: 0.075 | X28: 0.08 | Y28: 0.08 | Z28: 0.085 | AA28: 0.065 | AB28: 0.065 | AC28: 0.035 | AD28: 0.075 | AE28: 0.08 | AF28: 0.12 | AG28: 0.08 | AH28: 0.08 | AI28: 0.055 | AJ28: 0.085 | AK28: 0.08 | AL28: =INDEX($B28:$AK28,$B$9+0) -> 0.085 | AM28: =INDEX($B28:$AK28,$B$9+1) -> 0.065 | AN28: =INDEX($B28:$AK28,$B$9+2) -> 0.065
A29: 10 | B29: 0.047 | C29: 0.088 | D29: 0.083083083 | E29: 0.044 | F29: 0.055 | G29: 0.08 | H29: 0.07 | I29: 0.07 | J29: 0.07 | K29: 0.075 | L29: 0.075 | M29: 0.075 | N29: 0.04 | O29: 0.08 | P29: 0.09 | Q29: 0.03 | R29: 0.085 | S29: 0.095 | T29: 0.045 | U29: 0.06 | V29: 0.07 | W29: 0.055 | X29: 0.065 | Y29: 0.065 | Z29: 0.085 | AA29: 0.07 | AB29: 0.07 | AC29: 0.04 | AD29: 0.09 | AE29: 0.1 | AF29: 0.13 | AG29: 0.1 | AH29: 0.1 | AI29: 0.04 | AJ29: 0.08 | AK29: 0.09 | AL29: =INDEX($B29:$AK29,$B$9+0) -> 0.085 | AM29: =INDEX($B29:$AK29,$B$9+1) -> 0.07 | AN29: =INDEX($B29:$AK29,$B$9+2) -> 0.07
A30: 11 | B30: 0.043 | C30: 0.085 | D30: 0.092092092 | E30: 0.038 | F30: 0.063 | G30: 0.074 | H30: 0.065 | I30: 0.07 | J30: 0.07 | K30: 0.07 | L30: 0.07 | M30: 0.07 | N30: 0.035 | O30: 0.065 | P30: 0.08 | Q30: 0.03 | R30: 0.065 | S30: 0.075 | T30: 0.025 | U30: 0.03 | V30: 0.035 | W30: 0.05 | X30: 0.06 | Y30: 0.06 | Z30: 0.09 | AA30: 0.075 | AB30: 0.075 | AC30: 0.04 | AD30: 0.09 | AE30: 0.105 | AF30: 0.13 | AG30: 0.11 | AH30: 0.11 | AI30: 0.035 | AJ30: 0.065 | AK30: 0.08 | AL30: =INDEX($B30:$AK30,$B$9+0) -> 0.09 | AM30: =INDEX($B30:$AK30,$B$9+1) -> 0.075 | AN30: =INDEX($B30:$AK30,$B$9+2) -> 0.075
... A42: 23 | B42: 0.024 | C42: 0.027 | D42: 0.023023023 | E42: 0.027 | F42: 0.027 | G42: 0.028 | H42: 0.004 | I42: 0.005 | J42: 0.005 | K42: 0.005 | L42: 0.005 | M42: 0.005 | N42: 0.035 | O42: 0.015 | P42: 0.025 | Q42: 0.04 | R42: 0.015 | S42: 0.025 | T42: 0.023 | U42: 0.044 | V42: 0.047 | W42: 0.005 | X42: 0.006 | Y42: 0.006 | Z42: 0 | AA42: 0.025 | AB42: 0.025 | AC42: 0 | AD42: 0 | AE42: 0 | AF42: 0 | AG42: 0 | AH42: 0 | AI42: 0.035 | AJ42: 0.015 | AK42: 0.025 | AL42: =INDEX($B42:$AK42,$B$9+0) -> 0 | AM42: =INDEX($B42:$AK42,$B$9+1) -> 0.025 | AN42: =INDEX($B42:$AK42,$B$9+2) -> 0.025
A43: Summe | B43: =SUM(B19:B42) -> 1 | C43: =SUM(C19:C42) -> 1 | D43: =SUM(D19:D42) -> 1 | E43: =SUM(E19:E42) -> 1 | F43: =SUM(F19:F42) -> 1 | G43: =SUM(G19:G42) -> 1 | H43: =SUM(H19:H42) -> 1 | I43: =SUM(I19:I42) -> 1 | ... AN43: =SUM(AN19:AN42) -> 1
A44: Quelle / Herleitung | B44: VDI 6002 Blatt 1, Anhang D, Bilder D2/D3/D4 und D1 (Quelle ZfS/Solarthermie-2000, große Wohngebäude > 100 Bewohner). Sonntag: Original-Summe 99,9 % (Rundung) — alle Stundenwerte mit 100/99,9 skaliert. Kennwerte: Mittel 28, Max Februar 32, Schwachlast 22 l/(P·d) bei 60 °C. | E44: VDI 6002 Blatt 2, Tabelle 3 (Stundenwerte) und Bild 3 (Wochenprofil, differenzierte Balken Mo–Fr). Werktagsspalte = Spalte "Dienstag bis Donnerstag" — die Richtlinie lässt diese ausdrücklich für Mo–Fr zu, wenn keine Tagesdifferenzierung möglich ist. Eigenprofile für Mo und Fr siehe Referenztabelle unten. | H44: VDI 6002 Blatt 2, Bild 8 (Mo–Fr), Bild 9 (Sa und So — die Richtlinie gibt für Sa und So ausdrücklich EIN gemeinsames Profil an) sowie Bild 7 (Wochenprofil). Balkenwerte aus den Diagrammen abgelesen; jede Spalte summiert exakt zu 100,0 %. | K44: VDI 6002 Blatt 2, Bild 10 — "alle Wochentage gleich", deshalb sind alle drei Tagtypspalten identisch besetzt. Wochenprofil nach Abschnitt 6.3.3: entspricht dem der Seniorenheime (Bild 7). Balkenwerte abgelesen; Summe exakt 100,0 %. | N44: Werktag: Bestandsprofil Version 1.0 (typisierter Tagesgang). Sa/So: Morgenspitze später und flacher, Vormittags-/Mittagsmaximum. Wochenfaktoren in Anlehnung an VDI 6002 Blatt 1 Anhang D. | Q44: Werktag: Bestandsprofil Version 1.0. Sa/So: Zapfung deutlich später, ausgeprägtes Vormittagsmaximum, höherer Wochenendanteil. | T44: Werktag: Bestandsprofil Version 1.0. Sa/So: Frühstücksspitze 1–2 h später, Wochenendbelegung leicht höher (Wochenfaktor 16 %). | W44: Werktag: Bestandsprofil Version 1.0. Sa/So: Morgenspitze weniger ausgeprägt (Charakteristik analog VDI 6002 Blatt 2, Bild 9), Sa = So. Für belastbare Werte den VDI-Typ "Seniorenheim (VDI 6002-2)" verwenden. | Z44: Werktag: Bestandsprofil Version 1.0. Sa/So: nahe null — der Wochenfaktor von je 2,5 % bildet die Grundlast (Reinigung, Einzelnutzer) ab; die Tagesform ist bewusst flach gehalten. | AC44: Werktag: Bestandsprofil Version 1.0 (Abendspitze). Sa/So: Wettkampf-/Turnierbetrieb — Spitzen am Vormittag und Nachmittag, Wochenendanteil deutlich erhöht (Sa 19 %, So 16 %). | AF44: Werktag: Bestandsprofil Version 1.0. Sa/So: nahe null — je 1,5 % Wochenfaktor als Grundlast (Vereins-/Hallennutzung, Reinigung). | AI44: Frei editierbar. Startwerte = MFH Wohnen. Hier gemessene Profile des konkreten Objekts eintragen (Stundenwerte und Wochenfaktoren). | AL44: folgt der Auswahl in B7
A45: Status | B45: VDI-Wert (digitalisiert, Tabellenwerte) | E45: VDI-Wert (Tabelle 3) / Wochenprofil aus Bild 3 abgelesen | H45: abgelesen (Bild 7/8/9, Blatt 2); Sa = So laut Richtlinie | K45: abgelesen (Bild 10, Blatt 2); alle Tage gleich | N45: generisch, anpassbar | Q45: generisch, anpassbar | T45: generisch, anpassbar | W45: generisch, anpassbar | Z45: generisch, anpassbar | AC45: generisch, anpassbar | AF45: generisch, anpassbar | AI45: Eingabe — frei editierbar | AL45: —
A47: 3 Wochenfaktoren — Anteil des Wochentags am Wochenbedarf (Σ je Zeile = 100 %)
A48: Nutzungstyp | B48: Mo | C48: Di | D48: Mi | E48: Do | F48: Fr | G48: Sa | H48: So | I48: Σ | J48: Quelle
A49: Wohnen groß (VDI 6002) | B49: 0.138 | C49: 0.138 | D49: 0.138 | E49: 0.138 | F49: 0.138 | G49: 0.15 | H49: 0.16 | I49: =SUM(B49:H49) -> 1 | J49: VDI 6002 Bl. 1, Bild D1/Anh. D
A50: Studentenwohnheim (VDI 6002-2) | B50: 0.14 | C50: 0.165 | D50: 0.17 | E50: 0.165 | F50: 0.14 | G50: 0.105 | H50: 0.115 | I50: =SUM(B50:H50) -> 1 | J50: VDI 6002 Bl. 2, Bild 3 (abgelesen)
A51: Seniorenheim (VDI 6002-2) | B51: 0.154 | C51: 0.154 | D51: 0.154 | E51: 0.154 | F51: 0.154 | G51: 0.115 | H51: 0.115 | I51: =SUM(B51:H51) -> 1 | J51: VDI 6002 Bl. 2, Bild 7 (abgelesen)
A52: Krankenhaus (VDI 6002-2) | B52: 0.154 | C52: 0.154 | D52: 0.154 | E52: 0.154 | F52: 0.154 | G52: 0.115 | H52: 0.115 | I52: =SUM(B52:H52) -> 1 | J52: VDI 6002 Bl. 2, Abschn. 6.3.3 → wie Bild 7
A53: MFH Wohnen | B53: 0.138 | C53: 0.138 | D53: 0.138 | E53: 0.138 | F53: 0.138 | G53: 0.15 | H53: 0.16 | I53: =SUM(B53:H53) -> 1 | J53: generisch, anpassbar
A54: EFH Wohnen | B54: 0.135 | C54: 0.135 | D54: 0.135 | E54: 0.135 | F54: 0.135 | G54: 0.155 | H54: 0.17 | I54: =SUM(B54:H54) -> 1 | J54: generisch, anpassbar
A55: Hotel | B55: 0.135 | C55: 0.135 | D55: 0.135 | E55: 0.135 | F55: 0.14 | G55: 0.16 | H55: 0.16 | I55: =SUM(B55:H55) -> 1 | J55: generisch, anpassbar
...

Sheet DIN 4708-2
A1: DIN 4708-2 — Bedarfskennzahl N aus Wohnungstypen (Version 2.1.2)
A2: Ermittelt die Bedarfskennzahl N aus Wohnungsanzahl, Zimmerzahl (→ Belegungszahl p) und der maßgebenden Zapfstellen-Ausstattung (→ Wärmebedarf w_v). Wirksam wird das Blatt nur, wenn auf dem Blatt 'Eingaben' (Abschnitt 7) die N-Ermittlung auf "DIN 4708-2 (Tabelle)" steht.
A4: 1 Wohnungstypen — bis 10 Zeilen
A5: N = Σ [ n · p · (v · w_v) ] / (p_b · w_b) mit p_b = 3,5 Personen und w_b = 5820 Wh der Einheitswohnung nach DIN 4708-1. v = Anzahl gleichwertiger Zapfstellen der Wohnung (Regelfall v = 1: nach Norm zählt i. d. R. nur die größte Zapfstelle je Wohnung).
A6: Gelb = Eingabe. Spalte "p manuell" leer lassen, um die Belegungszahl aus der Nachschlagetabelle (Abschnitt 2) zu übernehmen; ein Eintrag überschreibt sie.
A7: Nr. | B7: Anzahl Wohnungen n | C7: Zimmer- zahl r | D7: p aus Tabelle | E7: p manuell (überschreibt) | F7: Belegungs- zahl p | G7: Ausstattung (maßgebende Zapfstelle) | H7: w_v [Wh] | I7: v [–] | J7: Personen n · p | K7: Beitrag n · p · (v · w_v) [Wh] | L7: Bemerkung
A8: 1 | B8: 20 | C8: 2 | D8: =IF($C8="","",IFERROR(INDEX($C$34:$C$46,MATCH($C8,$B$34:$B$46,1)),"")) -> 2 | F8: =IF($E8<>"",$E8,IF($D8="",0,$D8)) -> 2 | G8: Brause mit Mischbatterie | H8: =IF($G8="","",IFERROR(INDEX($C$51:$C$55,MATCH($G8,$B$51:$B$55,0)),"")) -> 3660 | I8: 1 | J8: =IF($B8="",0,$B8*$F8) -> 40 | K8: =IF(OR($B8="",$G8=""),0,$B8*$F8*IF($I8="",1,$I8)*$H8) -> 146400 | L8: Beispielzeile — bitte durch Projektdaten ersetzen
A9: 2 | B9: 10 | C9: 4 | D9: =IF($C9="","",IFERROR(INDEX($C$34:$C$46,MATCH($C9,$B$34:$B$46,1)),"")) -> 3.5 | F9: =IF($E9<>"",$E9,IF($D9="",0,$D9)) -> 3.5 | G9: Normalwanne (NB1, 1600 mm) | H9: =IF($G9="","",IFERROR(INDEX($C$51:$C$55,MATCH($G9,$B$51:$B$55,0)),"")) -> 5820 | I9: 1 | J9: =IF($B9="",0,$B9*$F9) -> 35 | K9: =IF(OR($B9="",$G9=""),0,$B9*$F9*IF($I9="",1,$I9)*$H9) -> 203700 | L9: Beispielzeile — bitte durch Projektdaten ersetzen
A10: 3 | D10: =IF($C10="","",IFERROR(INDEX($C$34:$C$46,MATCH($C10,$B$34:$B$46,1)),"")) | F10: =IF($E10<>"",$E10,IF($D10="",0,$D10)) -> 0 | H10: =IF($G10="","",IFERROR(INDEX($C$51:$C$55,MATCH($G10,$B$51:$B$55,0)),"")) | J10: =IF($B10="",0,$B10*$F10) -> 0 | K10: =IF(OR($B10="",$G10=""),0,$B10*$F10*IF($I10="",1,$I10)*$H10) -> 0
A11: 4 | D11: =IF($C11="","",IFERROR(INDEX($C$34:$C$46,MATCH($C11,$B$34:$B$46,1)),"")) | F11: =IF($E11<>"",$E11,IF($D11="",0,$D11)) -> 0 | H11: =IF($G11="","",IFERROR(INDEX($C$51:$C$55,MATCH($G11,$B$51:$B$55,0)),"")) | J11: =IF($B11="",0,$B11*$F11) -> 0 | K11: =IF(OR($B11="",$G11=""),0,$B11*$F11*IF($I11="",1,$I11)*$H11) -> 0
A12: 5 | D12: =IF($C12="","",IFERROR(INDEX($C$34:$C$46,MATCH($C12,$B$34:$B$46,1)),"")) | F12: =IF($E12<>"",$E12,IF($D12="",0,$D12)) -> 0 | H12: =IF($G12="","",IFERROR(INDEX($C$51:$C$55,MATCH($G12,$B$51:$B$55,0)),"")) | J12: =IF($B12="",0,$B12*$F12) -> 0 | K12: =IF(OR($B12="",$G12=""),0,$B12*$F12*IF($I12="",1,$I12)*$H12) -> 0
A13: 6 | D13: =IF($C13="","",IFERROR(INDEX($C$34:$C$46,MATCH($C13,$B$34:$B$46,1)),"")) | F13: =IF($E13<>"",$E13,IF($D13="",0,$D13)) -> 0 | H13: =IF($G13="","",IFERROR(INDEX($C$51:$C$55,MATCH($G13,$B$51:$B$55,0)),"")) | J13: =IF($B13="",0,$B13*$F13) -> 0 | K13: =IF(OR($B13="",$G13=""),0,$B13*$F13*IF($I13="",1,$I13)*$H13) -> 0
A14: 7 | D14: =IF($C14="","",IFERROR(INDEX($C$34:$C$46,MATCH($C14,$B$34:$B$46,1)),"")) | F14: =IF($E14<>"",$E14,IF($D14="",0,$D14)) -> 0 | H14: =IF($G14="","",IFERROR(INDEX($C$51:$C$55,MATCH($G14,$B$51:$B$55,0)),"")) | J14: =IF($B14="",0,$B14*$F14) -> 0 | K14: =IF(OR($B14="",$G14=""),0,$B14*$F14*IF($I14="",1,$I14)*$H14) -> 0
A15: 8 | D15: =IF($C15="","",IFERROR(INDEX($C$34:$C$46,MATCH($C15,$B$34:$B$46,1)),"")) | F15: =IF($E15<>"",$E15,IF($D15="",0,$D15)) -> 0 | H15: =IF($G15="","",IFERROR(INDEX($C$51:$C$55,MATCH($G15,$B$51:$B$55,0)),"")) | J15: =IF($B15="",0,$B15*$F15) -> 0 | K15: =IF(OR($B15="",$G15=""),0,$B15*$F15*IF($I15="",1,$I15)*$H15) -> 0
A16: 9 | D16: =IF($C16="","",IFERROR(INDEX($C$34:$C$46,MATCH($C16,$B$34:$B$46,1)),"")) | F16: =IF($E16<>"",$E16,IF($D16="",0,$D16)) -> 0 | H16: =IF($G16="","",IFERROR(INDEX($C$51:$C$55,MATCH($G16,$B$51:$B$55,0)),"")) | J16: =IF($B16="",0,$B16*$F16) -> 0 | K16: =IF(OR($B16="",$G16=""),0,$B16*$F16*IF($I16="",1,$I16)*$H16) -> 0
A17: 10 | D17: =IF($C17="","",IFERROR(INDEX($C$34:$C$46,MATCH($C17,$B$34:$B$46,1)),"")) | F17: =IF($E17<>"",$E17,IF($D17="",0,$D17)) -> 0 | H17: =IF($G17="","",IFERROR(INDEX($C$51:$C$55,MATCH($G17,$B$51:$B$55,0)),"")) | J17: =IF($B17="",0,$B17*$F17) -> 0 | K17: =IF(OR($B17="",$G17=""),0,$B17*$F17*IF($I17="",1,$I17)*$H17) -> 0
B18: =SUM(B8:B17) -> 30 | G18: Summe | J18: =SUM(J8:J17) -> 75 | K18: =SUM(K8:K17) -> 350100 | L18: Σ Wohnungen | Σ Personen | Σ Beiträge
A20: 1b Ergebnis der Tabelle
A21: Σ Beiträge Σ[n · p · (v · w_v)] | B21: =K18 -> 350100 | C21: Wh | D21: = Summe der Spalte K
A22: Einheitswohnung p_b | B22: =Berechnung!$B$373 -> 3.5 | C22: P | D22: aus 'Berechnung' B373 — DIN 4708-1
A23: Einheitswohnung w_b | B23: =Berechnung!$B$376 -> 5820 | C23: Wh | D23: aus 'Berechnung' B376 — DIN 4708-1
A24: Bezugswert p_b · w_b | B24: =B22*B23 -> 20370 | C24: Wh | D24: = 3,5 × 5820 = 20.370 Wh
A25: Bedarfskennzahl N (DIN 4708-2) | B25: =IFERROR(B21/B24,0) -> 17.18704 | C25: – | D25: = Σ Beiträge / (p_b · w_b)
A26: Σ Wohnungen Σn | B26: =B18 -> 30 | C26: WE | D26: = Summe Spalte B
A27: Σ Personen Σ(n · p) | B27: =J18 -> 75 | C27: P | D27: Bezugsgröße für den GLF-Faustwert bei Tabellenwahl
A28: mittlere Belegung Σ(n·p)/Σn | B28: =IFERROR(B27/B26,0) -> 2.5 | C28: P/WE | D28: = Personen gesamt / Wohnungen gesamt
A29: Kontrolle Tabelle | B29: =IF($B$26=0,"HINWEIS: Noch keine Wohnungszeile ausgefüllt — das Blatt liefert N = 0.",IF(SUMPRODUCT(--($B$8:$B$17<>""),--($G$8:$G$17=""))>0,"WARNUNG: In mindestens einer Zeile fehlt die Ausstattung — diese Zeile liefert keinen Beitrag.",IF(SUMPRODUCT(--($B$8:$B$17<>""),--($F$8:$F$17=0))>0,"WARNUNG: In mindestens einer Zeile ist die Belegungszahl p = 0 — Zimmerzahl r prüfen oder p manuell setzen.","OK: "&ROUND($B$26,0)&" Wohnungen, "&ROUND($B$27,1)&" Personen, N = "&ROUND($B$25,2)&"."))) -> OK: 30 Wohnungen, 75 Personen, N = 17,19.
A30: Handrechnung zur Kontrolle | B30: Beispiel 20 × 2-Zi. (Brause) + 10 × 4-Zi. (NB1): N = [20 · 2,0 · 3660 + 10 · 3,5 · 5820] / (3,5 · 5820) = 350.100 / 20.370 = 17,19
A32: 2 Nachschlagetabelle Belegungszahl p über Zimmerzahl r (editierbar)
A33: Werte nach Sekundärliteratur zu DIN 4708-2 (z. B. Recknagel) — vor Verwendung gegen den Normtext prüfen | B33: Zimmerzahl r | C33: Belegungszahl p | D33: Zuordnung
B34: 1 | C34: 2 | D34: 1 Zi. | E34: Aufsteigend sortiert halten — die Zuordnung erfolgt über MATCH(...;1) und übernimmt bei Zwischenwerten die nächstkleinere Zeile; r > 7 → p = 5,6.
B35: 1.5 | C35: 2 | D35: 1,5 Zi.
B36: 2 | C36: 2 | D36: 2 Zi.
B37: 2.5 | C37: 2.3 | D37: 2,5 Zi.
B38: 3 | C38: 2.7 | D38: 3 Zi.
B39: 3.5 | C39: 3.1 | D39: 3,5 Zi.
B40: 4 | C40: 3.5 | D40: 4 Zi. = Einheitswohnung
B41: 4.5 | C41: 3.9 | D41: 4,5 Zi.
B42: 5 | C42: 4.3 | D42: 5 Zi.
B43: 5.5 | C43: 4.6 | D43: 5,5 Zi.
...

Sheet Berechnung
A1: Berechnung — drei Verfahren (Version 2.1.2)
A2: Rechenblatt. Alle Eingangsgrößen stammen aus den Blättern 'Eingaben' und 'Zapfprofil'.
A3: 1 Grundwerte
A4: Personen gesamt (maßgebend) | B4: =Eingaben!$B$58 -> 75 | C4: P | D4: aus 'Eingaben' B58 — bei DIN-4708-2-Wahl Σ(n × p)
A5: spez. Tagesbedarf (angesetzt) | B5: =Eingaben!B19 -> 17.6 | C5: l/(Einheit·d) | D5: bei 60 °C
A6: Tagesbedarf Volumen V_60 | B6: =Eingaben!B11*B5 -> 1056 | C6: l/d | D6: = Einheiten × spez. Tagesbedarf
A7: Bezugstemperatur der Richtwerte | B7: 60 | C7: °C | D7: Konstante: Richtwerte sind auf 60 °C bezogen
A8: Temperaturhub Zapfung | B8: =B7-Eingaben!B23 -> 50 | C8: K | D8: = Bezugstemperatur − T_KW
A9: Tagesbedarf Zapfung Q_zapf | B9: =B6*B8*1.163/1000 -> 61.4064 | C9: kWh/d | D9: = V_60 × ΔT × 1,163 Wh/(l·K) / 1000
A10: Zirkulationsverluste je Tag | B10: =Eingaben!B29*24 -> 4.8 | C10: kWh/d | D10: = Zirkulationsleistung × 24 h
A11: Tagesbedarf gesamt | B11: =B9+B10 -> 66.2064 | C11: kWh/d | D11: Zapfung + Zirkulation
A12: Ladeleistung P_lade | B12: =Eingaben!B28 -> 4 | C12: kW | D12: konstant über 24 h
A13: Ladeenergie je Tag | B13: =B12*24 -> 96 | C13: kWh/d | D13: = P_lade × 24 h
A14: Plausibilität Ladeleistung | B14: =IF($B$13>=$B$11,"OK: P_lade × 24 h deckt den mittleren Tagesbedarf.","WARNUNG: P_lade × 24 h < Tagesbedarf — Speichervolumen ersetzt keine Ladeleistung!") -> OK: P_lade × 24 h deckt den mittleren Tagesbedarf.
A15: rechnerische Mindest-Ladeleistung | B15: =B11/24 -> 2.7586 | C15: kW | D15: = Tagesbedarf / 24 h
A16: Saisonfaktor | B16: =Zapfprofil!B8 -> 1 | C16: – | D16: aus 'Zapfprofil' B8 — skaliert den gesamten Zapfbedarf
A17: Wochenbedarf Zapfung Q_woche | B17: =7*B9 -> 429.8448 | C17: kWh/Woche | D17: = 7 × mittlerer Tagesbedarf Zapfung (ohne Zirkulation, ohne Saisonfaktor)
A19: 2 Profilbasiert — Stundenbilanz über 14 Tage (336 h, Mo–So × 2)
A20: Stundenbedarf(t) = Q_woche × Wochenfaktor(Wochentag) × Stundenanteil(Tagtyp) × Saisonfaktor + Zirkulationsleistung × 1 h. Lindley-Rekursion: Defizit(t) = MAX(0; Defizit(t−1) + Bedarf(t) − P_lade·1 h). Das Maximum über alle 336 h ist das maßgebende Defizit D_max. Zwei identische Wochen stellen sicher, dass der Einschwingzustand keine Rolle spielt; maßgebend ist die zweite Woche (Tag 8–14).
D21: t | E21: Tag | F21: WT-Nr | G21: Wochen- tag | H21: Stunde | I21: Tagtyp | J21: Wochen- faktor | K21: Profil- anteil | L21: Zapfbedarf [kWh/h] | M21: Zirkulation [kWh/h] | N21: Bedarf ges. [kWh/h] | O21: Ladung [kWh/h] | P21: Netto [kWh/h] | Q21: Defizit kum. [kWh] | R21: Label | S21: Speicher- füllstand [kWh]
D22: 1 | E22: =INT((D22-1)/24)+1 -> 1 | F22: =MOD(E22-1,7)+1 -> 1 | G22: =CHOOSE(F22,"Mo","Di","Mi","Do","Fr","Sa","So") -> Mo | H22: =MOD(D22-1,24) -> 0 | I22: =IF(F22<=5,"Werktag",IF(F22=6,"Samstag","Sonntag")) -> Werktag | J22: =INDEX(Zapfprofil!$B$61:$H$61,F22) -> 0.19 | K22: =INDEX(Zapfprofil!$AL$19:$AN$42,H22+1,IF(F22<=5,1,IF(F22=6,2,3))) -> 0 | L22: =$B$17*J22*K22*$B$16 -> 0 | M22: =Eingaben!$B$29 -> 0.2 | N22: =L22+M22 -> 0.2 | O22: =$B$12 -> 4 | P22: =N22-O22 -> -3.8 | Q22: =MAX(0,P22) -> 0 | R22: =G22&" "&RIGHT("0"&H22,2)&":00" -> Mo 00:00 | S22: =MAX(0,$B$419-Q22) -> 37.216 | T22: Woche 1 (Einschwingen)
D23: 2 | E23: =INT((D23-1)/24)+1 -> 1 | F23: =MOD(E23-1,7)+1 -> 1 | G23: =CHOOSE(F23,"Mo","Di","Mi","Do","Fr","Sa","So") -> Mo | H23: =MOD(D23-1,24) -> 1 | I23: =IF(F23<=5,"Werktag",IF(F23=6,"Samstag","Sonntag")) -> Werktag | J23: =INDEX(Zapfprofil!$B$61:$H$61,F23) -> 0.19 | K23: =INDEX(Zapfprofil!$AL$19:$AN$42,H23+1,IF(F23<=5,1,IF(F23=6,2,3))) -> 0 | L23: =$B$17*J23*K23*$B$16 -> 0 | M23: =Eingaben!$B$29 -> 0.2 | N23: =L23+M23 -> 0.2 | O23: =$B$12 -> 4 | P23: =N23-O23 -> -3.8 | Q23: =MAX(0,Q22+P23) -> 0 | R23: =G23&" "&RIGHT("0"&H23,2)&":00" -> Mo 01:00 | S23: =MAX(0,$B$419-Q23) -> 37.216
D24: 3 | E24: =INT((D24-1)/24)+1 -> 1 | F24: =MOD(E24-1,7)+1 -> 1 | G24: =CHOOSE(F24,"Mo","Di","Mi","Do","Fr","Sa","So") -> Mo | H24: =MOD(D24-1,24) -> 2 | I24: =IF(F24<=5,"Werktag",IF(F24=6,"Samstag","Sonntag")) -> Werktag | J24: =INDEX(Zapfprofil!$B$61:$H$61,F24) -> 0.19 | K24: =INDEX(Zapfprofil!$AL$19:$AN$42,H24+1,IF(F24<=5,1,IF(F24=6,2,3))) -> 0 | L24: =$B$17*J24*K24*$B$16 -> 0 | M24: =Eingaben!$B$29 -> 0.2 | N24: =L24+M24 -> 0.2 | O24: =$B$12 -> 4 | P24: =N24-O24 -> -3.8 | Q24: =MAX(0,Q23+P24) -> 0 | R24: =G24&" "&RIGHT("0"&H24,2)&":00" -> Mo 02:00 | S24: =MAX(0,$B$419-Q24) -> 37.216
D25: 4 | E25: =INT((D25-1)/24)+1 -> 1 | F25: =MOD(E25-1,7)+1 -> 1 | G25: =CHOOSE(F25,"Mo","Di","Mi","Do","Fr","Sa","So") -> Mo | H25: =MOD(D25-1,24) -> 3 | I25: =IF(F25<=5,"Werktag",IF(F25=6,"Samstag","Sonntag")) -> Werktag | J25: =INDEX(Zapfprofil!$B$61:$H$61,F25) -> 0.19 | K25: =INDEX(Zapfprofil!$AL$19:$AN$42,H25+1,IF(F25<=5,1,IF(F25=6,2,3))) -> 0 | L25: =$B$17*J25*K25*$B$16 -> 0 | M25: =Eingaben!$B$29 -> 0.2 | N25: =L25+M25 -> 0.2 | O25: =$B$12 -> 4 | P25: =N25-O25 -> -3.8 | Q25: =MAX(0,Q24+P25) -> 0 | R25: =G25&" "&RIGHT("0"&H25,2)&":00" -> Mo 03:00 | S25: =MAX(0,$B$419-Q25) -> 37.216
D26: 5 | E26: =INT((D26-1)/24)+1 -> 1 | F26: =MOD(E26-1,7)+1 -> 1 | G26: =CHOOSE(F26,"Mo","Di","Mi","Do","Fr","Sa","So") -> Mo | H26: =MOD(D26-1,24) -> 4 | I26: =IF(F26<=5,"Werktag",IF(F26=6,"Samstag","Sonntag")) -> Werktag | J26: =INDEX(Zapfprofil!$B$61:$H$61,F26) -> 0.19 | K26: =INDEX(Zapfprofil!$AL$19:$AN$42,H26+1,IF(F26<=5,1,IF(F26=6,2,3))) -> 0 | L26: =$B$17*J26*K26*$B$16 -> 0 | M26: =Eingaben!$B$29 -> 0.2 | N26: =L26+M26 -> 0.2 | O26: =$B$12 -> 4 | P26: =N26-O26 -> -3.8 | Q26: =MAX(0,Q25+P26) -> 0 | R26: =G26&" "&RIGHT("0"&H26,2)&":00" -> Mo 04:00 | S26: =MAX(0,$B$419-Q26) -> 37.216
D27: 6 | E27: =INT((D27-1)/24)+1 -> 1 | F27: =MOD(E27-1,7)+1 -> 1 | G27: =CHOOSE(F27,"Mo","Di","Mi","Do","Fr","Sa","So") -> Mo | H27: =MOD(D27-1,24) -> 5 | I27: =IF(F27<=5,"Werktag",IF(F27=6,"Samstag","Sonntag")) -> Werktag | J27: =INDEX(Zapfprofil!$B$61:$H$61,F27) -> 0.19 | K27: =INDEX(Zapfprofil!$AL$19:$AN$42,H27+1,IF(F27<=5,1,IF(F27=6,2,3))) -> 0 | L27: =$B$17*J27*K27*$B$16 -> 0 | M27: =Eingaben!$B$29 -> 0.2 | N27: =L27+M27 -> 0.2 | O27: =$B$12 -> 4 | P27: =N27-O27 -> -3.8 | Q27: =MAX(0,Q26+P27) -> 0 | R27: =G27&" "&RIGHT("0"&H27,2)&":00" -> Mo 05:00 | S27: =MAX(0,$B$419-Q27) -> 37.216
D28: 7 | E28: =INT((D28-1)/24)+1 -> 1 | F28: =MOD(E28-1,7)+1 -> 1 | G28: =CHOOSE(F28,"Mo","Di","Mi","Do","Fr","Sa","So") -> Mo | H28: =MOD(D28-1,24) -> 6 | I28: =IF(F28<=5,"Werktag",IF(F28=6,"Samstag","Sonntag")) -> Werktag | J28: =INDEX(Zapfprofil!$B$61:$H$61,F28) -> 0.19 | K28: =INDEX(Zapfprofil!$AL$19:$AN$42,H28+1,IF(F28<=5,1,IF(F28=6,2,3))) -> 0.02 | L28: =$B$17*J28*K28*$B$16 -> 1.6334102 | M28: =Eingaben!$B$29 -> 0.2 | N28: =L28+M28 -> 1.8334102 | O28: =$B$12 -> 4 | P28: =N28-O28 -> -2.1665898 | Q28: =MAX(0,Q27+P28) -> 0 | R28: =G28&" "&RIGHT("0"&H28,2)&":00" -> Mo 06:00 | S28: =MAX(0,$B$419-Q28) -> 37.216
D29: 8 | E29: =INT((D29-1)/24)+1 -> 1 | F29: =MOD(E29-1,7)+1 -> 1 | G29: =CHOOSE(F29,"Mo","Di","Mi","Do","Fr","Sa","So") -> Mo | H29: =MOD(D29-1,24) -> 7 | I29: =IF(F29<=5,"Werktag",IF(F29=6,"Samstag","Sonntag")) -> Werktag | J29: =INDEX(Zapfprofil!$B$61:$H$61,F29) -> 0.19 | K29: =INDEX(Zapfprofil!$AL$19:$AN$42,H29+1,IF(F29<=5,1,IF(F29=6,2,3))) -> 0.06 | L29: =$B$17*J29*K29*$B$16 -> 4.9002307 | M29: =Eingaben!$B$29 -> 0.2 | N29: =L29+M29 -> 5.1002307 | O29: =$B$12 -> 4 | P29: =N29-O29 -> 1.1002307 | Q29: =MAX(0,Q28+P29) -> 1.1002307 | R29: =G29&" "&RIGHT("0"&H29,2)&":00" -> Mo 07:00 | S29: =MAX(0,$B$419-Q29) -> 36.115769
D30: 9 | E30: =INT((D30-1)/24)+1 -> 1 | F30: =MOD(E30-1,7)+1 -> 1 | G30: =CHOOSE(F30,"Mo","Di","Mi","Do","Fr","Sa","So") -> Mo | H30: =MOD(D30-1,24) -> 8 | I30: =IF(F30<=5,"Werktag",IF(F30=6,"Samstag","Sonntag")) -> Werktag | J30: =INDEX(Zapfprofil!$B$61:$H$61,F30) -> 0.19 | K30: =INDEX(Zapfprofil!$AL$19:$AN$42,H30+1,IF(F30<=5,1,IF(F30=6,2,3))) -> 0.08 | L30: =$B$17*J30*K30*$B$16 -> 6.533641 | M30: =Eingaben!$B$29 -> 0.2 | N30: =L30+M30 -> 6.733641 | O30: =$B$12 -> 4 | P30: =N30-O30 -> 2.733641 | Q30: =MAX(0,Q29+P30) -> 3.8338717 | R30: =G30&" "&RIGHT("0"&H30,2)&":00" -> Mo 08:00 | S30: =MAX(0,$B$419-Q30) -> 33.382128
D31: 10 | E31: =INT((D31-1)/24)+1 -> 1 | F31: =MOD(E31-1,7)+1 -> 1 | G31: =CHOOSE(F31,"Mo","Di","Mi","Do","Fr","Sa","So") -> Mo | H31: =MOD(D31-1,24) -> 9 | I31: =IF(F31<=5,"Werktag",IF(F31=6,"Samstag","Sonntag")) -> Werktag | J31: =INDEX(Zapfprofil!$B$61:$H$61,F31) -> 0.19 | K31: =INDEX(Zapfprofil!$AL$19:$AN$42,H31+1,IF(F31<=5,1,IF(F31=6,2,3))) -> 0.085 | L31: =$B$17*J31*K31*$B$16 -> 6.9419935 | M31: =Eingaben!$B$29 -> 0.2 | N31: =L31+M31 -> 7.1419935 | O31: =$B$12 -> 4 | P31: =N31-O31 -> 3.1419935 | Q31: =MAX(0,Q30+P31) -> 6.9758652 | R31: =G31&" "&RIGHT("0"&H31,2)&":00" -> Mo 09:00 | S31: =MAX(0,$B$419-Q31) -> 30.240135
D32: 11 | E32: =INT((D32-1)/24)+1 -> 1 | F32: =MOD(E32-1,7)+1 -> 1 | G32: =CHOOSE(F32,"Mo","Di","Mi","Do","Fr","Sa","So") -> Mo | H32: =MOD(D32-1,24) -> 10 | I32: =IF(F32<=5,"Werktag",IF(F32=6,"Samstag","Sonntag")) -> Werktag | J32: =INDEX(Zapfprofil!$B$61:$H$61,F32) -> 0.19 | K32: =INDEX(Zapfprofil!$AL$19:$AN$42,H32+1,IF(F32<=5,1,IF(F32=6,2,3))) -> 0.085 | L32: =$B$17*J32*K32*$B$16 -> 6.9419935 | M32: =Eingaben!$B$29 -> 0.2 | N32: =L32+M32 -> 7.1419935 | O32: =$B$12 -> 4 | P32: =N32-O32 -> 3.1419935 | Q32: =MAX(0,Q31+P32) -> 10.117859 | R32: =G32&" "&RIGHT("0"&H32,2)&":00" -> Mo 10:00 | S32: =MAX(0,$B$419-Q32) -> 27.098141
D33: 12 | E33: =INT((D33-1)/24)+1 -> 1 | F33: =MOD(E33-1,7)+1 -> 1 | G33: =CHOOSE(F33,"Mo","Di","Mi","Do","Fr","Sa","So") -> Mo | H33: =MOD(D33-1,24) -> 11 | I33: =IF(F33<=5,"Werktag",IF(F33=6,"Samstag","Sonntag")) -> Werktag | J33: =INDEX(Zapfprofil!$B$61:$H$61,F33) -> 0.19 | K33: =INDEX(Zapfprofil!$AL$19:$AN$42,H33+1,IF(F33<=5,1,IF(F33=6,2,3))) -> 0.09 | L33: =$B$17*J33*K33*$B$16 -> 7.3503461 | M33: =Eingaben!$B$29 -> 0.2 | N33: =L33+M33 -> 7.5503461 | O33: =$B$12 -> 4 | P33: =N33-O33 -> 3.5503461 | Q33: =MAX(0,Q32+P33) -> 13.668205 | R33: =G33&" "&RIGHT("0"&H33,2)&":00" -> Mo 11:00 | S33: =MAX(0,$B$419-Q33) -> 23.547795
D34: 13 | E34: =INT((D34-1)/24)+1 -> 1 | F34: =MOD(E34-1,7)+1 -> 1 | G34: =CHOOSE(F34,"Mo","Di","Mi","Do","Fr","Sa","So") -> Mo | H34: =MOD(D34-1,24) -> 12 | I34: =IF(F34<=5,"Werktag",IF(F34=6,"Samstag","Sonntag")) -> Werktag | J34: =INDEX(Zapfprofil!$B$61:$H$61,F34) -> 0.19 | K34: =INDEX(Zapfprofil!$AL$19:$AN$42,H34+1,IF(F34<=5,1,IF(F34=6,2,3))) -> 0.1 | L34: =$B$17*J34*K34*$B$16 -> 8.1670512 | M34: =Eingaben!$B$29 -> 0.2 | N34: =L34+M34 -> 8.3670512 | O34: =$B$12 -> 4 | P34: =N34-O34 -> 4.3670512 | Q34: =MAX(0,Q33+P34) -> 18.035256 | R34: =G34&" "&RIGHT("0"&H34,2)&":00" -> Mo 12:00 | S34: =MAX(0,$B$419-Q34) -> 19.180744
... D189: 168 | E189: =INT((D189-1)/24)+1 -> 7 | F189: =MOD(E189-1,7)+1 -> 7 | G189: =CHOOSE(F189,"Mo","Di","Mi","Do","Fr","Sa","So") -> So | H189: =MOD(D189-1,24) -> 23 | I189: =IF(F189<=5,"Werktag",IF(F189=6,"Samstag","Sonntag")) -> Sonntag | J189: =INDEX(Zapfprofil!$B$61:$H$61,F189) -> 0.025 | K189: =INDEX(Zapfprofil!$AL$19:$AN$42,H189+1,IF(F189<=5,1,IF(F189=6,2,3))) -> 0.025 | L189: =$B$17*J189*K189*$B$16 -> 0.268653 | M189: =Eingaben!$B$29 -> 0.2 | N189: =L189+M189 -> 0.468653 | O189: =$B$12 -> 4 | P189: =N189-O189 -> -3.531347 | Q189: =MAX(0,Q188+P189) -> 0 | R189: =G189&" "&RIGHT("0"&H189,2)&":00" -> So 23:00 | S189: =MAX(0,$B$419-Q189) -> 37.216
D190: 169 | E190: =INT((D190-1)/24)+1 -> 8 | F190: =MOD(E190-1,7)+1 -> 1 | G190: =CHOOSE(F190,"Mo","Di","Mi","Do","Fr","Sa","So") -> Mo | H190: =MOD(D190-1,24) -> 0 | I190: =IF(F190<=5,"Werktag",IF(F190=6,"Samstag","Sonntag")) -> Werktag | J190: =INDEX(Zapfprofil!$B$61:$H$61,F190) -> 0.19 | K190: =INDEX(Zapfprofil!$AL$19:$AN$42,H190+1,IF(F190<=5,1,IF(F190=6,2,3))) -> 0 | L190: =$B$17*J190*K190*$B$16 -> 0 | M190: =Eingaben!$B$29 -> 0.2 | N190: =L190+M190 -> 0.2 | O190: =$B$12 -> 4 | P190: =N190-O190 -> -3.8 | Q190: =MAX(0,Q189+P190) -> 0 | R190: =G190&" "&RIGHT("0"&H190,2)&":00" -> Mo 00:00 | S190: =MAX(0,$B$419-Q190) -> 37.216 | T190: Woche 2 — maßgebend (Tag 8–14)
D191: 170 | E191: =INT((D191-1)/24)+1 -> 8 | F191: =MOD(E191-1,7)+1 -> 1 | G191: =CHOOSE(F191,"Mo","Di","Mi","Do","Fr","Sa","So") -> Mo | H191: =MOD(D191-1,24) -> 1 | I191: =IF(F191<=5,"Werktag",IF(F191=6,"Samstag","Sonntag")) -> Werktag | J191: =INDEX(Zapfprofil!$B$61:$H$61,F191) -> 0.19 | K191: =INDEX(Zapfprofil!$AL$19:$AN$42,H191+1,IF(F191<=5,1,IF(F191=6,2,3))) -> 0 | L191: =$B$17*J191*K191*$B$16 -> 0 | M191: =Eingaben!$B$29 -> 0.2 | N191: =L191+M191 -> 0.2 | O191: =$B$12 -> 4 | P191: =N191-O191 -> -3.8 | Q191: =MAX(0,Q190+P191) -> 0 | R191: =G191&" "&RIGHT("0"&H191,2)&":00" -> Mo 01:00 | S191: =MAX(0,$B$419-Q191) -> 37.216
D192: 171 | E192: =INT((D192-1)/24)+1 -> 8 | F192: =MOD(E192-1,7)+1 -> 1 | G192: =CHOOSE(F192,"Mo","Di","Mi","Do","Fr","Sa","So") -> Mo | H192: =MOD(D192-1,24) -> 2 | I192: =IF(F192<=5,"Werktag",IF(F192=6,"Samstag","Sonntag")) -> Werktag | J192: =INDEX(Zapfprofil!$B$61:$H$61,F192) -> 0.19 | K192: =INDEX(Zapfprofil!$AL$19:$AN$42,H192+1,IF(F192<=5,1,IF(F192=6,2,3))) -> 0 | L192: =$B$17*J192*K192*$B$16 -> 0 | M192: =Eingaben!$B$29 -> 0.2 | N192: =L192+M192 -> 0.2 | O192: =$B$12 -> 4 | P192: =N192-O192 -> -3.8 | Q192: =MAX(0,Q191+P192) -> 0 | R192: =G192&" "&RIGHT("0"&H192,2)&":00" -> Mo 02:00 | S192: =MAX(0,$B$419-Q192) -> 37.216
D193: 172 | E193: =INT((D193-1)/24)+1 -> 8 | F193: =MOD(E193-1,7)+1 -> 1 | G193: =CHOOSE(F193,"Mo","Di","Mi","Do","Fr","Sa","So") -> Mo | H193: =MOD(D193-1,24) -> 3 | I193: =IF(F193<=5,"Werktag",IF(F193=6,"Samstag","Sonntag")) -> Werktag | J193: =INDEX(Zapfprofil!$B$61:$H$61,F193) -> 0.19 | K193: =INDEX(Zapfprofil!$AL$19:$AN$42,H193+1,IF(F193<=5,1,IF(F193=6,2,3))) -> 0 | L193: =$B$17*J193*K193*$B$16 -> 0 | M193: =Eingaben!$B$29 -> 0.2 | N193: =L193+M193 -> 0.2 | O193: =$B$12 -> 4 | P193: =N193-O193 -> -3.8 | Q193: =MAX(0,Q192+P193) -> 0 | R193: =G193&" "&RIGHT("0"&H193,2)&":00" -> Mo 03:00 | S193: =MAX(0,$B$419-Q193) -> 37.216
D194: 173 | E194: =INT((D194-1)/24)+1 -> 8 | F194: =MOD(E194-1,7)+1 -> 1 | G194: =CHOOSE(F194,"Mo","Di","Mi","Do","Fr","Sa","So") -> Mo | H194: =MOD(D194-1,24) -> 4 | I194: =IF(F194<=5,"Werktag",IF(F194=6,"Samstag","Sonntag")) -> Werktag | J194: =INDEX(Zapfprofil!$B$61:$H$61,F194) -> 0.19 | K194: =INDEX(Zapfprofil!$AL$19:$AN$42,H194+1,IF(F194<=5,1,IF(F194=6,2,3))) -> 0 | L194: =$B$17*J194*K194*$B$16 -> 0 | M194: =Eingaben!$B$29 -> 0.2 | N194: =L194+M194 -> 0.2 | O194: =$B$12 -> 4 | P194: =N194-O194 -> -3.8 | Q194: =MAX(0,Q193+P194) -> 0 | R194: =G194&" "&RIGHT("0"&H194,2)&":00" -> Mo 04:00 | S194: =MAX(0,$B$419-Q194) -> 37.216
D195: 174 | E195: =INT((D195-1)/24)+1 -> 8 | F195: =MOD(E195-1,7)+1 -> 1 | G195: =CHOOSE(F195,"Mo","Di","Mi","Do","Fr","Sa","So") -> Mo | H195: =MOD(D195-1,24) -> 5 | I195: =IF(F195<=5,"Werktag",IF(F195=6,"Samstag","Sonntag")) -> Werktag | J195: =INDEX(Zapfprofil!$B$61:$H$61,F195) -> 0.19 | K195: =INDEX(Zapfprofil!$AL$19:$AN$42,H195+1,IF(F195<=5,1,IF(F195=6,2,3))) -> 0 | L195: =$B$17*J195*K195*$B$16 -> 0 | M195: =Eingaben!$B$29 -> 0.2 | N195: =L195+M195 -> 0.2 | O195: =$B$12 -> 4 | P195: =N195-O195 -> -3.8 | Q195: =MAX(0,Q194+P195) -> 0 | R195: =G195&" "&RIGHT("0"&H195,2)&":00" -> Mo 05:00 | S195: =MAX(0,$B$419-Q195) -> 37.216
...

Sheet Ergebnis
A1: Ergebnis — Speicherauslegung Trinkwarmwasser (Version 2.1.2)
A2: Gegenüberstellung der drei Verfahren und Empfehlung.
A4: Objekt | B4: =Eingaben!B5 -> Musterprojekt Beispielstraße 1
A5: Datum | B5: =Eingaben!B7 -> 46232
A6: Nutzungstyp | B6: =Eingaben!B10 -> Büro/Verwaltung
A7: Umfang | B7: =Eingaben!B11&" Einheiten × "&Eingaben!B12&" P = "&ROUND(Eingaben!B13,1)&" Personen" -> 60 Einheiten × 2,2 P = 132 Personen
A8: Zapfprofil | B8: =Zapfprofil!B7 -> Büro/Verwaltung
A9: Saisonfaktor | B9: =Zapfprofil!B8 -> 1
A11: 1 Verfahrensvergleich
A12: Verfahren | B12: Volumen [l] | C12: Kennwert | D12: Methodik (Kurzfassung) | E12: Zahlwert [l] — Hilfsspalte für die Logik
A13: DIN 4708 | B13: =$E$13 -> 489.37864 | C13: ="W_z = "&ROUND(Berechnung!$B$382,1)&" kWh" -> W_z = 22,8 kWh | D13: Bedarfskennzahl N, Wärmebedarf der Zapfperiode W_z(N) = 5820·[N·K(u1)+√N·K(u2)] Wh; V = W_z/(1,163·ΔT)/f_nutz (ohne Zuschlag). | E13: =Berechnung!$B$384 -> 489.37864
A14: Profilbasiert | B14: =IF($E$14<=0,"–",$E$14) -> 773.6323 | C14: ="D_max = "&ROUND(Berechnung!$B$359,1)&" kWh" -> D_max = 31,3 kWh | D14: Kumuliertes Energiedefizit über eine 336-h-Stundenbilanz (14 Tage, Mo–So × 2) mit Werktag-/Samstag-/Sonntag-Profil und Wochenfaktoren bei konstanter Ladeleistung — kein Speicherladezustand, sondern die über die Zeit aufsummierte Unterdeckung: Defizit(t)=MAX(0;Defizit(t−1)+Bedarf(t)−P_lade·1h); V = D_max/(1,163·ΔT)/f_nutz·(1+Zuschlag). | E14: =Berechnung!$B$368 -> 773.6323
A15: Faustwert mit Gleichzeitigkeit (GLF) | B15: =$E$15 -> 790.99305 | C15: =Berechnung!$B$405&" | V_spitze,p = "&ROUND(Berechnung!$B$407,1)&" l/P" -> GLF(17,2) = 0,26 | V_spitze,p = 35,8 l/P | D15: V = Personen × V_spitze,p × GLF(N) × (1 + Zuschlag); V_spitze,p = W_z(1)/3,5 / (1,163·ΔT) / f_nutz; GLF(N) = W_z(1)/W_z(N) nach DIN 4708. | E15: =Berechnung!$B$409 -> 790.99305
A16: klassischer Faustwert (ohne GLF, 1 Ladung/Tag) | B16: =$E$16 -> 3018.75 | C16: ="V60 = "&ROUND(Berechnung!$B$390,0)&" l/d" -> V60 = 2625 l/d | D16: NUR NACHRICHTLICH — geht nicht in die Empfehlung ein: 35 l/(Person·d) bei 60 °C, energiegleich auf T_Speicher umgerechnet, zzgl. Zuschlag. Unterstellt eine Speicherladung je Tag und wächst linear mit der Personenzahl. | E16: =Berechnung!$B$391 -> 3018.75
A17: Gleichzeitigkeitsfaktor | B17: =Berechnung!$B$405 -> GLF(17,2) = 0,26 | D17: GLF(N) = W_z(1) / W_z(N) nach DIN 4708 — Verhältnis des Zapfperioden-Wärmebedarfs einer Einheitswohnung zu dem von N Einheitswohnungen.
A18: Hinweis profilbasiert | B18: =IF($E$14<=0,"Ladeleistung deckt jede Stundenlast — keine Speicherung auf Stundenbasis nötig. Zapfspitzen unter 1 h (z. B. Wannenfüllung) sind im Stundenprofil nicht sichtbar; maßgebend ist dann das DIN-4708-Verfahren.","Zapfspitzen unter 1 h (z. B. Wannenfüllung) sind im Stundenprofil nicht sichtbar; maßgebend ist dann das DIN-4708-Verfahren.") -> Zapfspitzen unter 1 h (z. B. Wannenfüllung) sind im Stundenprofil nicht sichtbar; maßgebend ist dann das DIN-4708-Verfahren.
A20: 2 Empfehlung
A21: Maßgebendes Verfahren | B21: =INDEX($A$13:$A$15,MATCH(MAX($E$13:$E$15),$E$13:$E$15,0)) -> Faustwert mit Gleichzeitigkeit (GLF) | D21: Maximum der drei Verfahren in der Hilfsspalte E; der klassische Faustwert (Zeile 16) bleibt ausgeschlossen.
A22: maßgebender Tag (profilbasiert) | B22: =IF(Berechnung!$B$413<=0,"—",Berechnung!$B$362&" (Tag "&Berechnung!$B$361&" von 14), "&RIGHT("0"&Berechnung!$B$363,2)&":00 Uhr") -> Mo (Tag 1 von 14), 17:00 Uhr | D22: Wochentag / Stunde des maximalen Speicherdefizits in der 336-h-Bilanz
A23: Hinweis Wochenende | B23: =Berechnung!$B$365 -> Der maßgebende Tag ist ein Werktag (Mo).
A24: Maximum der Verfahren (ungerundet) | B24: =MAX($E$13:$E$15) -> 790.99305 | C24: l
A25: Empfehlung — nächstgrößere marktübliche Größe | B25: =IF($B$24<=MIN($A$40:$A$53),MIN($A$40:$A$53),IF($B$24>MAX($A$40:$A$53),CEILING($B$24,1000),INDEX($A$40:$A$53,MATCH($B$24,$A$40:$A$53,1)+IF(INDEX($A$40:$A$53,MATCH($B$24,$A$40:$A$53,1))>=$B$24,0,1)))) -> 800 | C25: l
A26: Leistungskennzahl | B26: ="Speicher mit NL ≥ "&ROUND(Berechnung!$B$374,1)&" wählen" -> Speicher mit NL ≥ 17,2 wählen | D26: Speicherauswahl nach Herstellerangabe N_L
A27: Speicherfüllstand (min., maßgebende Woche) | B27: =Berechnung!$B$420 -> 5.9208918 | C27: kWh | D27: ="nutzbare Speicherkapazität C_sp = "&ROUND(Berechnung!$B$419,1)&" kWh bei "&ROUND(Berechnung!$B$417,0)&" l und f_nutz = "&ROUND(Eingaben!$B$30*100,0)&" %; Restreserve "&ROUND(Berechnung!$B$421*100,1)&" %" -> nutzbare Speicherkapazität C_sp = 37,2 kWh bei 800 l und f_nutz = 80 %; Restreserve 15,9 %
A29: 3 Hinweise und Warnungen
A30: Legionellenschutz | B30: =IF($B$25>400,_xlfn._LONGTEXT("Großanlage (> 400 l Speicherinhalt bzw. > 3 l Rohrleitungsinhalt je Strang, DVGW W 551): Speicheraustritt dauerhaft ≥ 60 °C, Zirkulationsrücklauf ≥ 55 °C, wöchentliche Erwärmung des gesamten Inhalts. Bei WP-Betrieb Frischwasserstation mit Pufferspeicher p","rüfen."),"Kleinanlage (≤ 400 l): erhöhte Anforderungen nach DVGW W 551 nicht zwingend; Speichertemperatur ≥ 60 °C bzw. periodische Aufheizung dennoch empfohlen.") -> Großanlage (> 400 l Speicherinhalt bzw. > 3 l Rohrleitungsinhalt je Strang, DVGW W 551): Speicheraustritt dauerhaft ≥ 60 °C, Zirkulationsrücklauf ≥ 55 °C, wöchentliche Erwärmung des gesamten Inhalts. Bei WP-Betrieb Frischwasserstation mit Pufferspeicher prüfen.
A31: Zapfprofil | B31: =IF(OR(ABS(Zapfprofil!$B$10-1)>0.005,ABS(Zapfprofil!$B$11-1)>0.005,ABS(Zapfprofil!$B$12-1)>0.005,ABS(Zapfprofil!$B$13-1)>0.005),"WARNUNG: Eine der Summenkontrollen auf dem Blatt 'Zapfprofil' liegt nicht bei 100 % (Werktag "&ROUND(Zapfprofil!$B$10*100,1)&" %, Sa "&ROUND(Zapfprofil!$B$11*100,1)&" %, So "&ROUND(Zapfprofil!$B$12*100,1)&" %, Wochenfaktoren "&ROUND(Zapfprofil!$B$13*100,1)&" %) — das profilbasierte Ergebnis ist verfälscht.","OK: Alle drei Tagesprofile und die Wochenfaktoren summieren zu 100 %.") -> OK: Alle drei Tagesprofile und die Wochenfaktoren summieren zu 100 %.
A32: Ladeleistung | B32: =IF(Berechnung!$B$13<Berechnung!$B$11,"WARNUNG: Ladeleistung "&ROUND(Berechnung!$B$12,1)&" kW deckt den Tagesbedarf von "&ROUND(Berechnung!$B$11,0)&" kWh/d nicht — mindestens "&ROUND(Berechnung!$B$15,1)&" kW Dauerladeleistung erforderlich. Das Defizit wächst dann über die 14 Tage an; Volumen ersetzt keine Leistung.","OK: Ladeleistung deckt den mittleren Tagesbedarf ("&ROUND(Berechnung!$B$13/Berechnung!$B$11,1)&" Speicherladungen je Tag rechnerisch möglich).") -> OK: Ladeleistung deckt den mittleren Tagesbedarf (1,5 Speicherladungen je Tag rechnerisch möglich).
A33: Spitzentag | B33: =IF(Berechnung!$B$413<=0,"—","Der Spitzentag trägt "&ROUND(INDEX(Zapfprofil!$B$61:$H$61,IF(Berechnung!$B$364="Sonntag",7,IF(Berechnung!$B$364="Samstag",6,1)))*100,1)&" % des Wochenbedarfs — Wochenfaktor des maßgebenden Tagtyps.") -> Der Spitzentag trägt 19 % des Wochenbedarfs — Wochenfaktor des maßgebenden Tagtyps.
A34: klassischer Faustwert | B34: =IF($E$16>3*MAX($E$13,$E$14,$E$15),_xlfn._LONGTEXT("HINWEIS: Der klassische Faustwert (ohne GLF) liegt mehr als um den Faktor 3 über den maßgebenden Verfahren. Er unterstellt eine Speicherladung je Tag und wächst linear mit der Personenzahl — für größere Anlagen systematisch zu hoch. Er wird deshalb nur na","chrichtlich ausgewiesen und geht nicht in die Empfehlung ein."),"OK: Die Verfahren liegen in einer plausiblen Bandbreite.") -> HINWEIS: Der klassische Faustwert (ohne GLF) liegt mehr als um den Faktor 3 über den maßgebenden Verfahren. Er unterstellt eine Speicherladung je Tag und wächst linear mit der Personenzahl — für größere Anlagen systematisch zu hoch. Er wird deshalb nur nachrichtlich ausgewiesen und geht nicht in die Empfehlung ein.
A35: Speichertemperatur | B35: =IF(Eingaben!$B$22<60,"WARNUNG: Speichertemperatur < 60 °C — Legionellenschutz gesondert nachweisen (thermische Desinfektion oder FriWa-Konzept).","OK: Speichertemperatur ≥ 60 °C.") -> OK: Speichertemperatur ≥ 60 °C.
A36: Bedarfskennzahl N | B36: ="N = "&ROUND(Berechnung!$B$374,2)&" ("&Eingaben!$B$53&") | "&Eingaben!$B$57 -> N = 17,19 (DIN 4708-2 (Tabelle)) | N vereinfacht = 37,71 | N nach DIN 4708-2 = 17,19 | Abweichung -54,4 % | angesetzt: N = 17,19 (DIN 4708-2 (Tabelle))
A37: Schätzhilfen | B37: ="P_lade = "&ROUND(Eingaben!$B$28,1)&" kW ("&Eingaben!$B$62&") | P_zirk = "&ROUND(Eingaben!$B$29,2)&" kW ("&Eingaben!$B$72&") | Sicherheitszuschlag "&ROUND(Eingaben!$B$31*100,0)&" %" -> P_lade = 4 kW (auto) | P_zirk = 0,2 kW (Leitungslänge) | Sicherheitszuschlag 15 %
A38: 4 Nachschlagetabelle marktübliche Speichergrößen (anpassbar)
A39: Nenninhalt [l]
A40: 100
A41: 150
A42: 200
A43: 300
A44: 400
...

Sheet Hilfe
A1: Hilfe — Kurzanleitung, Methodik, Grenzen (Version 2.1.2)
B3: 1 Kurzanleitung
B4: 1. Blatt 'Eingaben': Projektdaten, Nutzungstyp, Anzahl Einheiten und Personen je Einheit eintragen. Nur gelb hinterlegte Zellen (blaue Schrift) sind Eingaben.
B5: 2. Spezifischen Tagesbedarf prüfen: 'auto' übernimmt den Richtwert der Tabelle unten auf demselben Blatt, 'manuell' verwendet den selbst eingetragenen Wert.
B6: 3. Temperaturen, Ladeleistung, Zirkulation, nutzbaren Speicheranteil und Sicherheitszuschlag anpassen.
B7: 4. Blatt 'Zapfprofil': Profil prüfen. '(automatisch)' folgt dem Nutzungstyp; alternativ ein anderes Profil oder 'Benutzerdefiniert' wählen. Je Nutzungstyp gibt es drei Tagtypen (Werktag / Samstag / Sonntag) und eine Zeile Wochenfaktoren. Alle vier Summenkontrollen müssen 100 % anzeigen.
B8: 5. Optional den Saisonfaktor setzen (Default 1,00). Beispiel: Februar-Maximum bei Wohngebäuden = 1,14 (32 statt 28 l/(P·d) nach VDI 6002 Blatt 1, Bild D1); sommerliche Schwachlast ≈ 0,79.
B9: 6. Optional Blatt 'DIN 4708-2': Wohnungstypen (Anzahl, Zimmerzahl, Ausstattung) eintragen und auf 'Eingaben' (Abschnitt 7) die N-Ermittlung auf "DIN 4708-2 (Tabelle)" umstellen. Die Kontrollzelle Eingaben!B57 zeigt beide N-Werte im Vergleich.
B10: 7. Optional die Schätzhilfen auf 'Eingaben' nutzen: Abschnitt 8 schlägt die WP-Ladeleistung aus max. Tagesbedarf / Ladezeitfenster vor, Abschnitt 9 den Zirkulationsverlust über Leitungslänge, Anteil am Tagesbedarf oder direkte kW-Eingabe.
B11: 8. Blatt 'Ergebnis': Verfahrensvergleich, maßgebender Tag, Empfehlung, Hinweise und Warnungen lesen. Das Blatt 'Berechnung' zeigt den vollständigen Rechenweg über 336 Stunden. Die Datei enthält keine Makros; es ist kein Blattschutz gesetzt — alle Zellen und Tabellen (Richtwerte, Profile, Wochenfaktoren, Nachschlagetabellen DIN 4708-2, Speichergrößen) dürfen angepasst werden.
B12: 2 Methodik (Kurzfassung)
B13: Verfahren 1 — DIN 4708 (Bedarfskennzahl):
B14: N = Einheiten × Personen je Einheit / 3,5 (Einheitswohnung: p = 3,5 Personen, v = w = 1) — alternativ N nach DIN 4708-2, siehe Abschnitt 3
... B79: Stand: Juli 2026 — INEKON, Version 2.1.2. Alle Richtwerte, Profile, Wochenfaktoren und Nachschlagetabellen in dieser Datei sind anpassbar und vom Bearbeiter fachlich zu verantworten.
