Workbook

Sheet Tab_BHKW
A1: ID | B1: Bezeichner | C1: Firma | D1: Beschreibung | E1: Ptherm | F1: Pel | G1: Brennstoff | H1: Wirkungsgrad | I1: Investition_kwel | J1: Raumbedarf | K1: Wartungskosten_kwhel | L1: Nutzungsdauer | M1: NOX | N1: SO2 | O1: CO | P1: CO2 | Q1: Staub | R1: Motortyp | S1: Grenzleistung | T1: Kosten_Modul | U1: Kosten_Montage | V1: Kosten_Lieferung | W1: Kosten_Schallschutzhaube | X1: Kosten_Abgasreinigung | Y1: Vorlauf | Z1: Ruecklauf
A2: 1 | B2: Agenitor 404 BG | bt135-0 | C2: 2G Energy AG | D2: BHKW-Modul, Biogas (50% CH4), 100 kWel | E2: 110 | F2: 100 | G2: 14 | H2: 38.6 | I2: =IF(ISNUMBER(SEARCH("Brennstoffzelle",$R2)),Kostenberechnung!$B$17,Kostenberechnung!$B$5*IF($G2=14,Kostenberechnung!$B$10*$F2^Kostenberechnung!$C$10,IF($G2=25,Kostenberechnung!$B$9*$F2^Kostenberechnung!$C$9*Kostenberechnung!$B$15,Kostenberechnung!$B$9*$F2^Kostenberechnung!$C$9))) -> 1325.7415 | J2: 3.13 | K2: =IF(ISNUMBER(SEARCH("Brennstoffzelle",$R2)),Kostenberechnung!$B$18/100,Kostenberechnung!$B$5*IF($G2=14,Kostenberechnung!$B$12*$F2^Kostenberechnung!$C$12,IF($G2=25,Kostenberechnung!$B$11*$F2^Kostenberechnung!$C$11*Kostenberechnung!$B$16,Kostenberechnung!$B$11*$F2^Kostenberechnung!$C$11))/100) -> 0.018871255 | M2: 500 | O2: 250 | R2: agenitor 404 BG | bt135 | S2: 105 | Y2: 90 | Z2: 70
A3: 2 | B3: Agenitor 404 EG | ct80-1 | C3: 2G Energy AG | D3: BHKW-Modul, Erdgas, 160 kWel | E3: 168 | F3: 160 | G3: 3 | H3: 41 | I3: =IF(ISNUMBER(SEARCH("Brennstoffzelle",$R3)),Kostenberechnung!$B$17,Kostenberechnung!$B$5*IF($G3=14,Kostenberechnung!$B$10*$F3^Kostenberechnung!$C$10,IF($G3=25,Kostenberechnung!$B$9*$F3^Kostenberechnung!$C$9*Kostenberechnung!$B$15,Kostenberechnung!$B$9*$F3^Kostenberechnung!$C$9))) -> 921.9081 | J3: 4.08 | K3: =IF(ISNUMBER(SEARCH("Brennstoffzelle",$R3)),Kostenberechnung!$B$18/100,Kostenberechnung!$B$5*IF($G3=14,Kostenberechnung!$B$12*$F3^Kostenberechnung!$C$12,IF($G3=25,Kostenberechnung!$B$11*$F3^Kostenberechnung!$C$11*Kostenberechnung!$B$16,Kostenberechnung!$B$11*$F3^Kostenberechnung!$C$11))/100) -> 0.0107005 | M3: 500 | O3: 250 | R3: agenitor 404 EG | ct80 | S3: 167 | Y3: 90 | Z3: 70
A4: 3 | B4: Agenitor 404c pure H2 | ct0-0 | C4: 2G Energy AG | D4: BHKW-Modul, 100% Wasserstoff, 115 kWel | E4: 129 | F4: 115 | G4: 25 | H4: 37.7 | I4: =IF(ISNUMBER(SEARCH("Brennstoffzelle",$R4)),Kostenberechnung!$B$17,Kostenberechnung!$B$5*IF($G4=14,Kostenberechnung!$B$10*$F4^Kostenberechnung!$C$10,IF($G4=25,Kostenberechnung!$B$9*$F4^Kostenberechnung!$C$9*Kostenberechnung!$B$15,Kostenberechnung!$B$9*$F4^Kostenberechnung!$C$9))) -> 1531.9753 | J4: 4.08 | K4: =IF(ISNUMBER(SEARCH("Brennstoffzelle",$R4)),Kostenberechnung!$B$18/100,Kostenberechnung!$B$5*IF($G4=14,Kostenberechnung!$B$12*$F4^Kostenberechnung!$C$12,IF($G4=25,Kostenberechnung!$B$11*$F4^Kostenberechnung!$C$11*Kostenberechnung!$B$16,Kostenberechnung!$B$11*$F4^Kostenberechnung!$C$11))/100) -> 0.01483103 | M4: 95 | O4: 1 | R4: agenitor 404 pure H2 | ct0 | S4: 121 | Y4: 90 | Z4: 70
A5: 4 | B5: Agenitor 406 BG | ct135-1 | C5: 2G Energy AG | D5: BHKW-Modul, Biogas (50% CH4), 250 kWel | E5: 245 | F5: 250 | G5: 14 | H5: 42.4 | I5: =IF(ISNUMBER(SEARCH("Brennstoffzelle",$R5)),Kostenberechnung!$B$17,Kostenberechnung!$B$5*IF($G5=14,Kostenberechnung!$B$10*$F5^Kostenberechnung!$C$10,IF($G5=25,Kostenberechnung!$B$9*$F5^Kostenberechnung!$C$9*Kostenberechnung!$B$15,Kostenberechnung!$B$9*$F5^Kostenberechnung!$C$9))) -> 811.26547 | J5: 4.43 | K5: =IF(ISNUMBER(SEARCH("Brennstoffzelle",$R5)),Kostenberechnung!$B$18/100,Kostenberechnung!$B$5*IF($G5=14,Kostenberechnung!$B$12*$F5^Kostenberechnung!$C$12,IF($G5=25,Kostenberechnung!$B$11*$F5^Kostenberechnung!$C$11*Kostenberechnung!$B$16,Kostenberechnung!$B$11*$F5^Kostenberechnung!$C$11))/100) -> 0.012178266 | M5: 500 | O5: 500 | R5: agenitor 406 BG | ct135 | S5: 261 | Y5: 90 | Z5: 70
A6: 5 | B6: Agenitor 406 EG | ct80-1 | C6: 2G Energy AG | D6: BHKW-Modul, Erdgas, 250 kWel | E6: 260 | F6: 250 | G6: 3 | H6: 41.8 | I6: =IF(ISNUMBER(SEARCH("Brennstoffzelle",$R6)),Kostenberechnung!$B$17,Kostenberechnung!$B$5*IF($G6=14,Kostenberechnung!$B$10*$F6^Kostenberechnung!$C$10,IF($G6=25,Kostenberechnung!$B$9*$F6^Kostenberechnung!$C$9*Kostenberechnung!$B$15,Kostenberechnung!$B$9*$F6^Kostenberechnung!$C$9))) -> 731.2991 | J6: 4.43 | K6: =IF(ISNUMBER(SEARCH("Brennstoffzelle",$R6)),Kostenberechnung!$B$18/100,Kostenberechnung!$B$5*IF($G6=14,Kostenberechnung!$B$12*$F6^Kostenberechnung!$C$12,IF($G6=25,Kostenberechnung!$B$11*$F6^Kostenberechnung!$C$11*Kostenberechnung!$B$16,Kostenberechnung!$B$11*$F6^Kostenberechnung!$C$11))/100) -> 0.0098130267 | M6: 500 | O6: 250 | R6: agenitor 406 EG | ct80 | S6: 261 | Y6: 90 | Z6: 70
A7: 6 | B7: Agenitor 406 pure H2 | ct0-0 | C7: 2G Energy AG | D7: BHKW-Modul, 100% Wasserstoff, 170 kWel | E7: 183 | F7: 170 | G7: 25 | H7: 39 | I7: =IF(ISNUMBER(SEARCH("Brennstoffzelle",$R7)),Kostenberechnung!$B$17,Kostenberechnung!$B$5*IF($G7=14,Kostenberechnung!$B$10*$F7^Kostenberechnung!$C$10,IF($G7=25,Kostenberechnung!$B$9*$F7^Kostenberechnung!$C$9*Kostenberechnung!$B$15,Kostenberechnung!$B$9*$F7^Kostenberechnung!$C$9))) -> 1250.6937 | J7: 4.43 | K7: =IF(ISNUMBER(SEARCH("Brennstoffzelle",$R7)),Kostenberechnung!$B$18/100,Kostenberechnung!$B$5*IF($G7=14,Kostenberechnung!$B$12*$F7^Kostenberechnung!$C$12,IF($G7=25,Kostenberechnung!$B$11*$F7^Kostenberechnung!$C$11*Kostenberechnung!$B$16,Kostenberechnung!$B$11*$F7^Kostenberechnung!$C$11))/100) -> 0.013748002 | M7: 95 | O7: 1 | R7: agenitor 406 pure H2 | ct0 | S7: 178 | Y7: 90 | Z7: 70
A8: 7 | B8: Agenitor 408 BG | ct135-1 | C8: 2G Energy AG | D8: BHKW-Modul, Biogas (50% CH4), 360 kWel | E8: 345 | F8: 360 | G8: 14 | H8: 42.5 | I8: =IF(ISNUMBER(SEARCH("Brennstoffzelle",$R8)),Kostenberechnung!$B$17,Kostenberechnung!$B$5*IF($G8=14,Kostenberechnung!$B$10*$F8^Kostenberechnung!$C$10,IF($G8=25,Kostenberechnung!$B$9*$F8^Kostenberechnung!$C$9*Kostenberechnung!$B$15,Kostenberechnung!$B$9*$F8^Kostenberechnung!$C$9))) -> 667.23788 | J8: 5.31 | K8: =IF(ISNUMBER(SEARCH("Brennstoffzelle",$R8)),Kostenberechnung!$B$18/100,Kostenberechnung!$B$5*IF($G8=14,Kostenberechnung!$B$12*$F8^Kostenberechnung!$C$12,IF($G8=25,Kostenberechnung!$B$11*$F8^Kostenberechnung!$C$11*Kostenberechnung!$B$16,Kostenberechnung!$B$11*$F8^Kostenberechnung!$C$11))/100) -> 0.010230296 | M8: 500 | O8: 500 | R8: agenitor 408 BG | ct135 | S8: 374 | Y8: 90 | Z8: 70
A9: 8 | B9: Agenitor 408 BG | ct135-0 | C9: 2G Energy AG | D9: BHKW-Modul, Biogas (50% CH4), 360 kWel | E9: 345 | F9: 360 | G9: 14 | H9: 42.5 | I9: =IF(ISNUMBER(SEARCH("Brennstoffzelle",$R9)),Kostenberechnung!$B$17,Kostenberechnung!$B$5*IF($G9=14,Kostenberechnung!$B$10*$F9^Kostenberechnung!$C$10,IF($G9=25,Kostenberechnung!$B$9*$F9^Kostenberechnung!$C$9*Kostenberechnung!$B$15,Kostenberechnung!$B$9*$F9^Kostenberechnung!$C$9))) -> 667.23788 | J9: 5.31 | K9: =IF(ISNUMBER(SEARCH("Brennstoffzelle",$R9)),Kostenberechnung!$B$18/100,Kostenberechnung!$B$5*IF($G9=14,Kostenberechnung!$B$12*$F9^Kostenberechnung!$C$12,IF($G9=25,Kostenberechnung!$B$11*$F9^Kostenberechnung!$C$11*Kostenberechnung!$B$16,Kostenberechnung!$B$11*$F9^Kostenberechnung!$C$11))/100) -> 0.010230296 | M9: 500 | O9: 250 | R9: agenitor 408 BG | ct135 | S9: 374 | Y9: 90 | Z9: 70
A10: 9 | B10: Agenitor 408 EG | ct80-1 | C10: 2G Energy AG | D10: BHKW-Modul, Erdgas, 360 kWel | E10: 381 | F10: 360 | G10: 3 | H10: 42.5 | I10: =IF(ISNUMBER(SEARCH("Brennstoffzelle",$R10)),Kostenberechnung!$B$17,Kostenberechnung!$B$5*IF($G10=14,Kostenberechnung!$B$10*$F10^Kostenberechnung!$C$10,IF($G10=25,Kostenberechnung!$B$9*$F10^Kostenberechnung!$C$9*Kostenberechnung!$B$15,Kostenberechnung!$B$9*$F10^Kostenberechnung!$C$9))) -> 605.20834 | J10: 5.51 | K10: =IF(ISNUMBER(SEARCH("Brennstoffzelle",$R10)),Kostenberechnung!$B$18/100,Kostenberechnung!$B$5*IF($G10=14,Kostenberechnung!$B$12*$F10^Kostenberechnung!$C$12,IF($G10=25,Kostenberechnung!$B$11*$F10^Kostenberechnung!$C$11*Kostenberechnung!$B$16,Kostenberechnung!$B$11*$F10^Kostenberechnung!$C$11))/100) -> 0.0091428302 | M10: 500 | O10: 250 | R10: agenitor 408 EG | ct80 | S10: 373 | Y10: 90 | Z10: 70
A11: 10 | B11: Agenitor 408 pure H2 | ct0-0 | C11: 2G Energy AG | D11: BHKW-Modul, 100% Wasserstoff, 240 kWel | E11: 250 | F11: 240 | G11: 25 | H11: 40.2 | I11: =IF(ISNUMBER(SEARCH("Brennstoffzelle",$R11)),Kostenberechnung!$B$17,Kostenberechnung!$B$5*IF($G11=14,Kostenberechnung!$B$10*$F11^Kostenberechnung!$C$10,IF($G11=25,Kostenberechnung!$B$9*$F11^Kostenberechnung!$C$9*Kostenberechnung!$B$15,Kostenberechnung!$B$9*$F11^Kostenberechnung!$C$9))) -> 1045.7414 | J11: 5.51 | K11: =IF(ISNUMBER(SEARCH("Brennstoffzelle",$R11)),Kostenberechnung!$B$18/100,Kostenberechnung!$B$5*IF($G11=14,Kostenberechnung!$B$12*$F11^Kostenberechnung!$C$12,IF($G11=25,Kostenberechnung!$B$11*$F11^Kostenberechnung!$C$11*Kostenberechnung!$B$16,Kostenberechnung!$B$11*$F11^Kostenberechnung!$C$11))/100) -> 0.012858364 | M11: 95 | O11: 1 | R11: agenitor 408 pure H2 | ct0 | S11: 250 | Y11: 90 | Z11: 70
A12: 11 | B12: Agenitor 412 BG | ct135-B-1 | C12: 2G Energy AG | D12: BHKW-Modul, Biogas (50% CH4), 500 kWel | E12: 482 | F12: 500 | G12: 14 | H12: 41.9 | I12: =IF(ISNUMBER(SEARCH("Brennstoffzelle",$R12)),Kostenberechnung!$B$17,Kostenberechnung!$B$5*IF($G12=14,Kostenberechnung!$B$10*$F12^Kostenberechnung!$C$10,IF($G12=25,Kostenberechnung!$B$9*$F12^Kostenberechnung!$C$9*Kostenberechnung!$B$15,Kostenberechnung!$B$9*$F12^Kostenberechnung!$C$9))) -> 559.51395 | J12: 5.95 | K12: =IF(ISNUMBER(SEARCH("Brennstoffzelle",$R12)),Kostenberechnung!$B$18/100,Kostenberechnung!$B$5*IF($G12=14,Kostenberechnung!$B$12*$F12^Kostenberechnung!$C$12,IF($G12=25,Kostenberechnung!$B$11*$F12^Kostenberechnung!$C$11*Kostenberechnung!$B$16,Kostenberechnung!$B$11*$F12^Kostenberechnung!$C$11))/100) -> 0.0087436574 | M12: 500 | O12: 250 | R12: agenitor 412 BG | ct135-B | S12: 620 | Y12: 90 | Z12: 70
A13: 12 | B13: Agenitor 412 EG | ct70-1 | C13: 2G Energy AG | D13: BHKW-Modul, Erdgas, 450 kWel | E13: 493 | F13: 450 | G13: 3 | H13: 41.3 | I13: =IF(ISNUMBER(SEARCH("Brennstoffzelle",$R13)),Kostenberechnung!$B$17,Kostenberechnung!$B$5*IF($G13=14,Kostenberechnung!$B$10*$F13^Kostenberechnung!$C$10,IF($G13=25,Kostenberechnung!$B$9*$F13^Kostenberechnung!$C$9*Kostenberechnung!$B$15,Kostenberechnung!$B$9*$F13^Kostenberechnung!$C$9))) -> 539.02463 | J13: 5.95 | K13: =IF(ISNUMBER(SEARCH("Brennstoffzelle",$R13)),Kostenberechnung!$B$18/100,Kostenberechnung!$B$5*IF($G13=14,Kostenberechnung!$B$12*$F13^Kostenberechnung!$C$12,IF($G13=25,Kostenberechnung!$B$11*$F13^Kostenberechnung!$C$11*Kostenberechnung!$B$16,Kostenberechnung!$B$11*$F13^Kostenberechnung!$C$11))/100) -> 0.0087554831 | M13: 500 | O13: 250 | R13: agenitor 412 EG | ct70 | S13: 468 | Y13: 90 | Z13: 70
A14: 13 | B14: Agenitor 420 EG | ct70-1 (avus 1000plus) | C14: 2G Energy AG | D14: BHKW-Modul, Erdgas, 999 kWel | E14: 1071 | F14: 999 | G14: 3 | H14: 40.9 | I14: =IF(ISNUMBER(SEARCH("Brennstoffzelle",$R14)),Kostenberechnung!$B$17,Kostenberechnung!$B$5*IF($G14=14,Kostenberechnung!$B$10*$F14^Kostenberechnung!$C$10,IF($G14=25,Kostenberechnung!$B$9*$F14^Kostenberechnung!$C$9*Kostenberechnung!$B$15,Kostenberechnung!$B$9*$F14^Kostenberechnung!$C$9))) -> 356.3292 | J14: 10.54 | K14: =IF(ISNUMBER(SEARCH("Brennstoffzelle",$R14)),Kostenberechnung!$B$18/100,Kostenberechnung!$B$5*IF($G14=14,Kostenberechnung!$B$12*$F14^Kostenberechnung!$C$12,IF($G14=25,Kostenberechnung!$B$11*$F14^Kostenberechnung!$C$11*Kostenberechnung!$B$16,Kostenberechnung!$B$11*$F14^Kostenberechnung!$C$11))/100) -> 0.0075004554 | M14: 250 | O14: 250 | R14: agenitor 420 EG | ct70 | S14: 1027 | Y14: 90 | Z14: 70
A15: 14 | B15: Agenitor 420 H2 | ct0-0 | C15: 2G Energy AG | D15: BHKW-Modul, 100% Wasserstoff, 750 kWel | E15: 747 | F15: 750 | G15: 25 | H15: 41.2 | I15: =IF(ISNUMBER(SEARCH("Brennstoffzelle",$R15)),Kostenberechnung!$B$17,Kostenberechnung!$B$5*IF($G15=14,Kostenberechnung!$B$10*$F15^Kostenberechnung!$C$10,IF($G15=25,Kostenberechnung!$B$9*$F15^Kostenberechnung!$C$9*Kostenberechnung!$B$15,Kostenberechnung!$B$9*$F15^Kostenberechnung!$C$9))) -> 578.89146 | K15: =IF(ISNUMBER(SEARCH("Brennstoffzelle",$R15)),Kostenberechnung!$B$18/100,Kostenberechnung!$B$5*IF($G15=14,Kostenberechnung!$B$12*$F15^Kostenberechnung!$C$12,IF($G15=25,Kostenberechnung!$B$11*$F15^Kostenberechnung!$C$11*Kostenberechnung!$B$16,Kostenberechnung!$B$11*$F15^Kostenberechnung!$C$11))/100) -> 0.010308247 | M15: 95 | O15: 1 | R15: agenitor 420 H2 | ct0 | S15: 770 | Y15: 90 | Z15: 70
A16: 15 | B16: avus 500plus EG | C16: 2G Energy AG | D16: BHKW-Modul, Erdgas, 550 kWel | E16: 585 | F16: 550 | G16: 3 | H16: 42.6 | I16: =IF(ISNUMBER(SEARCH("Brennstoffzelle",$R16)),Kostenberechnung!$B$17,Kostenberechnung!$B$5*IF($G16=14,Kostenberechnung!$B$10*$F16^Kostenberechnung!$C$10,IF($G16=25,Kostenberechnung!$B$9*$F16^Kostenberechnung!$C$9*Kostenberechnung!$B$15,Kostenberechnung!$B$9*$F16^Kostenberechnung!$C$9))) -> 485.71069 | J16: 5.97 | K16: =IF(ISNUMBER(SEARCH("Brennstoffzelle",$R16)),Kostenberechnung!$B$18/100,Kostenberechnung!$B$5*IF($G16=14,Kostenberechnung!$B$12*$F16^Kostenberechnung!$C$12,IF($G16=25,Kostenberechnung!$B$11*$F16^Kostenberechnung!$C$11*Kostenberechnung!$B$16,Kostenberechnung!$B$11*$F16^Kostenberechnung!$C$11))/100) -> 0.0084211805 | M16: 500 | O16: 300 | R16: avus 500plus EG (V-Motor) | S16: 569 | Y16: 90 | Z16: 70
A17: 16 | B17: EC-POWER XRGI 6 | C17: EC POWER A/S | D17: BHKW (Power Unit), Erdgas, 6,0 kWel | E17: 12.4 | F17: 6 | G17: 3 | H17: 30.1 | I17: =IF(ISNUMBER(SEARCH("Brennstoffzelle",$R17)),Kostenberechnung!$B$17,Kostenberechnung!$B$5*IF($G17=14,Kostenberechnung!$B$10*$F17^Kostenberechnung!$C$10,IF($G17=25,Kostenberechnung!$B$9*$F17^Kostenberechnung!$C$9*Kostenberechnung!$B$15,Kostenberechnung!$B$9*$F17^Kostenberechnung!$C$9))) -> 5067.1692 | J17: 0.59 | K17: =IF(ISNUMBER(SEARCH("Brennstoffzelle",$R17)),Kostenberechnung!$B$18/100,Kostenberechnung!$B$5*IF($G17=14,Kostenberechnung!$B$12*$F17^Kostenberechnung!$C$12,IF($G17=25,Kostenberechnung!$B$11*$F17^Kostenberechnung!$C$11*Kostenberechnung!$B$16,Kostenberechnung!$B$11*$F17^Kostenberechnung!$C$11))/100) -> 0.020232148 | M17: 240 | O17: 150 | Y17: 80 | Z17: 70
A18: 17 | B18: EC-POWER XRGI 6 LowNOx | C18: EC POWER A/S | D18: BHKW (Power Unit), Erdgas, Low-NOx, 6,0 kWel | E18: 14.6 | F18: 6 | G18: 3 | H18: 27.9 | I18: =IF(ISNUMBER(SEARCH("Brennstoffzelle",$R18)),Kostenberechnung!$B$17,Kostenberechnung!$B$5*IF($G18=14,Kostenberechnung!$B$10*$F18^Kostenberechnung!$C$10,IF($G18=25,Kostenberechnung!$B$9*$F18^Kostenberechnung!$C$9*Kostenberechnung!$B$15,Kostenberechnung!$B$9*$F18^Kostenberechnung!$C$9))) -> 5067.1692 | J18: 0.59 | K18: =IF(ISNUMBER(SEARCH("Brennstoffzelle",$R18)),Kostenberechnung!$B$18/100,Kostenberechnung!$B$5*IF($G18=14,Kostenberechnung!$B$12*$F18^Kostenberechnung!$C$12,IF($G18=25,Kostenberechnung!$B$11*$F18^Kostenberechnung!$C$11*Kostenberechnung!$B$16,Kostenberechnung!$B$11*$F18^Kostenberechnung!$C$11))/100) -> 0.020232148 | M18: 240 | O18: 150 | Y18: 80 | Z18: 70
A19: 18 | B19: EC-POWER XRGI 9 | C19: EC POWER A/S | D19: BHKW (Power Unit), Erdgas, 9,0 kWel | E19: 20.1 | F19: 9 | G19: 3 | H19: 29.3 | I19: =IF(ISNUMBER(SEARCH("Brennstoffzelle",$R19)),Kostenberechnung!$B$17,Kostenberechnung!$B$5*IF($G19=14,Kostenberechnung!$B$10*$F19^Kostenberechnung!$C$10,IF($G19=25,Kostenberechnung!$B$9*$F19^Kostenberechnung!$C$9*Kostenberechnung!$B$15,Kostenberechnung!$B$9*$F19^Kostenberechnung!$C$9))) -> 4105.5755 | J19: 0.59 | K19: =IF(ISNUMBER(SEARCH("Brennstoffzelle",$R19)),Kostenberechnung!$B$18/100,Kostenberechnung!$B$5*IF($G19=14,Kostenberechnung!$B$12*$F19^Kostenberechnung!$C$12,IF($G19=25,Kostenberechnung!$B$11*$F19^Kostenberechnung!$C$11*Kostenberechnung!$B$16,Kostenberechnung!$B$11*$F19^Kostenberechnung!$C$11))/100) -> 0.018701666 | M19: 240 | O19: 70 | Y19: 80 | Z19: 70
A20: 19 | B20: EC-POWER XRGI 15 | C20: EC POWER A/S | D20: BHKW (Power Unit), Erdgas, 14,5 kWel | E20: 30.8 | F20: 14.5 | G20: 3 | H20: 29.5 | I20: =IF(ISNUMBER(SEARCH("Brennstoffzelle",$R20)),Kostenberechnung!$B$17,Kostenberechnung!$B$5*IF($G20=14,Kostenberechnung!$B$10*$F20^Kostenberechnung!$C$10,IF($G20=25,Kostenberechnung!$B$9*$F20^Kostenberechnung!$C$9*Kostenberechnung!$B$15,Kostenberechnung!$B$9*$F20^Kostenberechnung!$C$9))) -> 3205.3533 | J20: 0.84 | K20: =IF(ISNUMBER(SEARCH("Brennstoffzelle",$R20)),Kostenberechnung!$B$18/100,Kostenberechnung!$B$5*IF($G20=14,Kostenberechnung!$B$12*$F20^Kostenberechnung!$C$12,IF($G20=25,Kostenberechnung!$B$11*$F20^Kostenberechnung!$C$11*Kostenberechnung!$B$16,Kostenberechnung!$B$11*$F20^Kostenberechnung!$C$11))/100) -> 0.017048962 | M20: 240 | O20: 150 | Y20: 85 | Z20: 75
A21: 20 | B21: EC-POWER XRGI 15 BIOGENIC | C21: EC POWER A/S | D21: BHKW (Power Unit), Biogas, 14,5 kWel | E21: 30.8 | F21: 14.5 | G21: 14 | H21: 29.5 | I21: =IF(ISNUMBER(SEARCH("Brennstoffzelle",$R21)),Kostenberechnung!$B$17,Kostenberechnung!$B$5*IF($G21=14,Kostenberechnung!$B$10*$F21^Kostenberechnung!$C$10,IF($G21=25,Kostenberechnung!$B$9*$F21^Kostenberechnung!$C$9*Kostenberechnung!$B$15,Kostenberechnung!$B$9*$F21^Kostenberechnung!$C$9))) -> 3732.2058 | J21: 0.84 | K21: =IF(ISNUMBER(SEARCH("Brennstoffzelle",$R21)),Kostenberechnung!$B$18/100,Kostenberechnung!$B$5*IF($G21=14,Kostenberechnung!$B$12*$F21^Kostenberechnung!$C$12,IF($G21=25,Kostenberechnung!$B$11*$F21^Kostenberechnung!$C$11*Kostenberechnung!$B$16,Kostenberechnung!$B$11*$F21^Kostenberechnung!$C$11))/100) -> 0.047497077 | M21: 240 | Y21: 85 | Z21: 75
A22: 21 | B22: EC-POWER XRGI 20 | C22: EC POWER A/S | D22: BHKW (Power Unit), Erdgas, 20,0 kWel | E22: 38.7 | F22: 20 | G22: 3 | H22: 32.7 | I22: =IF(ISNUMBER(SEARCH("Brennstoffzelle",$R22)),Kostenberechnung!$B$17,Kostenberechnung!$B$5*IF($G22=14,Kostenberechnung!$B$10*$F22^Kostenberechnung!$C$10,IF($G22=25,Kostenberechnung!$B$9*$F22^Kostenberechnung!$C$9*Kostenberechnung!$B$15,Kostenberechnung!$B$9*$F22^Kostenberechnung!$C$9))) -> 2712.6348 | J22: 0.84 | K22: =IF(ISNUMBER(SEARCH("Brennstoffzelle",$R22)),Kostenberechnung!$B$18/100,Kostenberechnung!$B$5*IF($G22=14,Kostenberechnung!$B$12*$F22^Kostenberechnung!$C$12,IF($G22=25,Kostenberechnung!$B$11*$F22^Kostenberechnung!$C$11*Kostenberechnung!$B$16,Kostenberechnung!$B$11*$F22^Kostenberechnung!$C$11))/100) -> 0.016017824 | M22: 240 | O22: 50 | Y22: 85 | Z22: 75
A23: 22 | B23: EC-POWER XRGI 25 | C23: EC POWER A/S | D23: BHKW (Power Unit), Erdgas, 24,0 kWel | E23: 48 | F23: 24 | G23: 3 | H23: 31.2 | I23: =IF(ISNUMBER(SEARCH("Brennstoffzelle",$R23)),Kostenberechnung!$B$17,Kostenberechnung!$B$5*IF($G23=14,Kostenberechnung!$B$10*$F23^Kostenberechnung!$C$10,IF($G23=25,Kostenberechnung!$B$9*$F23^Kostenberechnung!$C$9*Kostenberechnung!$B$15,Kostenberechnung!$B$9*$F23^Kostenberechnung!$C$9))) -> 2467.7222 | J23: 0.84 | K23: =IF(ISNUMBER(SEARCH("Brennstoffzelle",$R23)),Kostenberechnung!$B$18/100,Kostenberechnung!$B$5*IF($G23=14,Kostenberechnung!$B$12*$F23^Kostenberechnung!$C$12,IF($G23=25,Kostenberechnung!$B$11*$F23^Kostenberechnung!$C$11*Kostenberechnung!$B$16,Kostenberechnung!$B$11*$F23^Kostenberechnung!$C$11))/100) -> 0.01546117 | Y23: 85 | Z23: 75
A24: 23 | B24: SenerTec Dachs 0.8 GenD | C24: SenerTec GmbH | D24: Brennstoffzellen-Heizgeraet (PEM), Erdgas + bis 20% H2 | E24: 1 | F24: 0.705 | G24: 3 | I24: =IF(ISNUMBER(SEARCH("Brennstoffzelle",$R24)),Kostenberechnung!$B$17,Kostenberechnung!$B$5*IF($G24=14,Kostenberechnung!$B$10*$F24^Kostenberechnung!$C$10,IF($G24=25,Kostenberechnung!$B$9*$F24^Kostenberechnung!$C$9*Kostenberechnung!$B$15,Kostenberechnung!$B$9*$F24^Kostenberechnung!$C$9))) -> 30000 | J24: 1.49 | K24: =IF(ISNUMBER(SEARCH("Brennstoffzelle",$R24)),Kostenberechnung!$B$18/100,Kostenberechnung!$B$5*IF($G24=14,Kostenberechnung!$B$12*$F24^Kostenberechnung!$C$12,IF($G24=25,Kostenberechnung!$B$11*$F24^Kostenberechnung!$C$11*Kostenberechnung!$B$16,Kostenberechnung!$B$11*$F24^Kostenberechnung!$C$11))/100) -> 0.035 | R24: PEM-Brennstoffzelle | Y24: 67 | Z24: 30
A25: 24 | B25: SenerTec Dachs Gen1.1 G5.5 | C25: SenerTec GmbH | D25: BHKW, Erdgas, 5,5 kWel (auch F5.5 Fluessiggas / HR5.3 Heizoel) | E25: 14.7 | F25: 5.5 | G25: 3 | H25: 24 | I25: =IF(ISNUMBER(SEARCH("Brennstoffzelle",$R25)),Kostenberechnung!$B$17,Kostenberechnung!$B$5*IF($G25=14,Kostenberechnung!$B$10*$F25^Kostenberechnung!$C$10,IF($G25=25,Kostenberechnung!$B$9*$F25^Kostenberechnung!$C$9*Kostenberechnung!$B$15,Kostenberechnung!$B$9*$F25^Kostenberechnung!$C$9))) -> 5301.2424 | J25: 0.77 | K25: =IF(ISNUMBER(SEARCH("Brennstoffzelle",$R25)),Kostenberechnung!$B$18/100,Kostenberechnung!$B$5*IF($G25=14,Kostenberechnung!$B$12*$F25^Kostenberechnung!$C$12,IF($G25=25,Kostenberechnung!$B$11*$F25^Kostenberechnung!$C$11*Kostenberechnung!$B$16,Kostenberechnung!$B$11*$F25^Kostenberechnung!$C$11))/100) -> 0.02057657 | R25: Verbrennungsmotor (Magermotor) | Y25: 83 | Z25: 70
A26: 25 | B26: SenerTec Dachs Gen2 2.9 (G2.9) | C26: SenerTec GmbH | D26: BHKW, Erdgas, 2,85 kWel (auch F3.0 Fluessiggas) | E26: 7 | F26: 2.85 | G26: 3 | H26: 29.8 | I26: =IF(ISNUMBER(SEARCH("Brennstoffzelle",$R26)),Kostenberechnung!$B$17,Kostenberechnung!$B$5*IF($G26=14,Kostenberechnung!$B$10*$F26^Kostenberechnung!$C$10,IF($G26=25,Kostenberechnung!$B$9*$F26^Kostenberechnung!$C$9*Kostenberechnung!$B$15,Kostenberechnung!$B$9*$F26^Kostenberechnung!$C$9))) -> 7456.9532 | J26: 0.77 | K26: =IF(ISNUMBER(SEARCH("Brennstoffzelle",$R26)),Kostenberechnung!$B$18/100,Kostenberechnung!$B$5*IF($G26=14,Kostenberechnung!$B$12*$F26^Kostenberechnung!$C$12,IF($G26=25,Kostenberechnung!$B$11*$F26^Kostenberechnung!$C$11*Kostenberechnung!$B$16,Kostenberechnung!$B$11*$F26^Kostenberechnung!$C$11))/100) -> 0.023375636 | R26: Verbrennungsmotor (Otto) | Y26: 83 | Z26: 70
A27: 26 | B27: SenerTec Dachs Gen2 5.5 (G5.5) | C27: SenerTec GmbH | D27: BHKW, Erdgas, 5,5 kWel (auch F5.5 Fluessiggas) | E27: 14.8 | F27: 5.5 | G27: 3 | H27: 28.4 | I27: =IF(ISNUMBER(SEARCH("Brennstoffzelle",$R27)),Kostenberechnung!$B$17,Kostenberechnung!$B$5*IF($G27=14,Kostenberechnung!$B$10*$F27^Kostenberechnung!$C$10,IF($G27=25,Kostenberechnung!$B$9*$F27^Kostenberechnung!$C$9*Kostenberechnung!$B$15,Kostenberechnung!$B$9*$F27^Kostenberechnung!$C$9))) -> 5301.2424 | J27: 0.77 | K27: =IF(ISNUMBER(SEARCH("Brennstoffzelle",$R27)),Kostenberechnung!$B$18/100,Kostenberechnung!$B$5*IF($G27=14,Kostenberechnung!$B$12*$F27^Kostenberechnung!$C$12,IF($G27=25,Kostenberechnung!$B$11*$F27^Kostenberechnung!$C$11*Kostenberechnung!$B$16,Kostenberechnung!$B$11*$F27^Kostenberechnung!$C$11))/100) -> 0.02057657 | R27: Verbrennungsmotor (Otto) | Y27: 83 | Z27: 70
A28: 27 | B28: SenerTec Dachs Gen2 G5.5 (EN) | C28: SenerTec GmbH | D28: BHKW, Erdgas, 5,5 kWel - engl. Datenblatt, identisch mit Dachs Gen2 5.5 | E28: 14.8 | F28: 5.5 | G28: 3 | H28: 28.4 | I28: =IF(ISNUMBER(SEARCH("Brennstoffzelle",$R28)),Kostenberechnung!$B$17,Kostenberechnung!$B$5*IF($G28=14,Kostenberechnung!$B$10*$F28^Kostenberechnung!$C$10,IF($G28=25,Kostenberechnung!$B$9*$F28^Kostenberechnung!$C$9*Kostenberechnung!$B$15,Kostenberechnung!$B$9*$F28^Kostenberechnung!$C$9))) -> 5301.2424 | J28: 0.77 | K28: =IF(ISNUMBER(SEARCH("Brennstoffzelle",$R28)),Kostenberechnung!$B$18/100,Kostenberechnung!$B$5*IF($G28=14,Kostenberechnung!$B$12*$F28^Kostenberechnung!$C$12,IF($G28=25,Kostenberechnung!$B$11*$F28^Kostenberechnung!$C$11*Kostenberechnung!$B$16,Kostenberechnung!$B$11*$F28^Kostenberechnung!$C$11))/100) -> 0.02057657 | R28: Verbrennungsmotor (Otto) | Y28: 83 | Z28: 70
A29: 28 | B29: SenerTec Dachs InnoGen | C29: SenerTec GmbH | D29: Brennstoffzellen-Heizgeraet (PEM), Erdgas | E29: 0.95 | F29: 0.7 | G29: 3 | H29: 37.7 | I29: =IF(ISNUMBER(SEARCH("Brennstoffzelle",$R29)),Kostenberechnung!$B$17,Kostenberechnung!$B$5*IF($G29=14,Kostenberechnung!$B$10*$F29^Kostenberechnung!$C$10,IF($G29=25,Kostenberechnung!$B$9*$F29^Kostenberechnung!$C$9*Kostenberechnung!$B$15,Kostenberechnung!$B$9*$F29^Kostenberechnung!$C$9))) -> 30000 | K29: =IF(ISNUMBER(SEARCH("Brennstoffzelle",$R29)),Kostenberechnung!$B$18/100,Kostenberechnung!$B$5*IF($G29=14,Kostenberechnung!$B$12*$F29^Kostenberechnung!$C$12,IF($G29=25,Kostenberechnung!$B$11*$F29^Kostenberechnung!$C$11*Kostenberechnung!$B$16,Kostenberechnung!$B$11*$F29^Kostenberechnung!$C$11))/100) -> 0.035 | R29: PEM-Brennstoffzelle
A30: 29 | B30: SenerTec Dachs Pro 20 (G20.0) | C30: SenerTec GmbH | D30: BHKW, Erdgas, 10-20 kWel (auch F20.0 Fluessiggas) | E30: 44 | F30: 20 | G30: 3 | H30: 32 | I30: =IF(ISNUMBER(SEARCH("Brennstoffzelle",$R30)),Kostenberechnung!$B$17,Kostenberechnung!$B$5*IF($G30=14,Kostenberechnung!$B$10*$F30^Kostenberechnung!$C$10,IF($G30=25,Kostenberechnung!$B$9*$F30^Kostenberechnung!$C$9*Kostenberechnung!$B$15,Kostenberechnung!$B$9*$F30^Kostenberechnung!$C$9))) -> 2712.6348 | K30: =IF(ISNUMBER(SEARCH("Brennstoffzelle",$R30)),Kostenberechnung!$B$18/100,Kostenberechnung!$B$5*IF($G30=14,Kostenberechnung!$B$12*$F30^Kostenberechnung!$C$12,IF($G30=25,Kostenberechnung!$B$11*$F30^Kostenberechnung!$C$11*Kostenberechnung!$B$16,Kostenberechnung!$B$11*$F30^Kostenberechnung!$C$11))/100) -> 0.016017824 | R30: Verbrennungsmotor (Otto)
A31: 30 | B31: avus 1200e | 12V4000L64FNER | C31: 2G Energy AG | D31: BHKW-Modul, Erdgas, 1519 kWel | E31: 1566 | F31: 1519 | G31: 3 | H31: 44.3 | I31: =IF(ISNUMBER(SEARCH("Brennstoffzelle",$R31)),Kostenberechnung!$B$17,Kostenberechnung!$B$5*IF($G31=14,Kostenberechnung!$B$10*$F31^Kostenberechnung!$C$10,IF($G31=25,Kostenberechnung!$B$9*$F31^Kostenberechnung!$C$9*Kostenberechnung!$B$15,Kostenberechnung!$B$9*$F31^Kostenberechnung!$C$9))) -> 286.68001 | J31: =4.8*1.9 -> 9.12 | K31: =IF(ISNUMBER(SEARCH("Brennstoffzelle",$R31)),Kostenberechnung!$B$18/100,Kostenberechnung!$B$5*IF($G31=14,Kostenberechnung!$B$12*$F31^Kostenberechnung!$C$12,IF($G31=25,Kostenberechnung!$B$11*$F31^Kostenberechnung!$C$11*Kostenberechnung!$B$16,Kostenberechnung!$B$11*$F31^Kostenberechnung!$C$11))/100) -> 0.006914824 | M31: 500 | O31: 1000 | R31: 12V4000L64FNER | Y31: 91 | Z31: 77
A32: 31 | B32: avus 1600e | 16V4000L64FNER | C32: 2G Energy AG | D32: BHKW-Modul, Erdgas, 2032 kWel | E32: 2147 | F32: 2032 | G32: 3 | H32: 44 | I32: =IF(ISNUMBER(SEARCH("Brennstoffzelle",$R32)),Kostenberechnung!$B$17,Kostenberechnung!$B$5*IF($G32=14,Kostenberechnung!$B$10*$F32^Kostenberechnung!$C$10,IF($G32=25,Kostenberechnung!$B$9*$F32^Kostenberechnung!$C$9*Kostenberechnung!$B$15,Kostenberechnung!$B$9*$F32^Kostenberechnung!$C$9))) -> 246.49806 | J32: =5.5*2.1 -> 11.55 | K32: =IF(ISNUMBER(SEARCH("Brennstoffzelle",$R32)),Kostenberechnung!$B$18/100,Kostenberechnung!$B$5*IF($G32=14,Kostenberechnung!$B$12*$F32^Kostenberechnung!$C$12,IF($G32=25,Kostenberechnung!$B$11*$F32^Kostenberechnung!$C$11*Kostenberechnung!$B$16,Kostenberechnung!$B$11*$F32^Kostenberechnung!$C$11))/100) -> 0.0065353092 | M32: 500 | O32: 1000 | R32: 16V4000L64FNER | Y32: 91 | Z32: 78
A33: 32 | B33: avus 2000e | 20V4000L64FNER | C33: 2G Energy AG | D33: BHKW-Modul, Erdgas, 2547 kWel | E33: 2683 | F33: 2547 | G33: 3 | H33: 44.1 | I33: =IF(ISNUMBER(SEARCH("Brennstoffzelle",$R33)),Kostenberechnung!$B$17,Kostenberechnung!$B$5*IF($G33=14,Kostenberechnung!$B$10*$F33^Kostenberechnung!$C$10,IF($G33=25,Kostenberechnung!$B$9*$F33^Kostenberechnung!$C$9*Kostenberechnung!$B$15,Kostenberechnung!$B$9*$F33^Kostenberechnung!$C$9))) -> 219.22843 | J33: =6.2*2.1 -> 13.02 | K33: =IF(ISNUMBER(SEARCH("Brennstoffzelle",$R33)),Kostenberechnung!$B$18/100,Kostenberechnung!$B$5*IF($G33=14,Kostenberechnung!$B$12*$F33^Kostenberechnung!$C$12,IF($G33=25,Kostenberechnung!$B$11*$F33^Kostenberechnung!$C$11*Kostenberechnung!$B$16,Kostenberechnung!$B$11*$F33^Kostenberechnung!$C$11))/100) -> 0.0062550923 | M33: 500 | O33: 1000 | R33: 20V4000L64FNER TR | Y33: 92 | Z33: 77
A34: 33 | B34: avus 1000plus | ct80-0 | C34: 2G Energy AG | D34: BHKW-Modul, Erdgas, 1035 kWel | E34: 1052 | F34: 1035 | G34: 3 | H34: 43.8 | I34: =IF(ISNUMBER(SEARCH("Brennstoffzelle",$R34)),Kostenberechnung!$B$17,Kostenberechnung!$B$5*IF($G34=14,Kostenberechnung!$B$10*$F34^Kostenberechnung!$C$10,IF($G34=25,Kostenberechnung!$B$9*$F34^Kostenberechnung!$C$9*Kostenberechnung!$B$15,Kostenberechnung!$B$9*$F34^Kostenberechnung!$C$9))) -> 349.84193 | J34: =6.295*1.675 -> 10.544125 | K34: =IF(ISNUMBER(SEARCH("Brennstoffzelle",$R34)),Kostenberechnung!$B$18/100,Kostenberechnung!$B$5*IF($G34=14,Kostenberechnung!$B$12*$F34^Kostenberechnung!$C$12,IF($G34=25,Kostenberechnung!$B$11*$F34^Kostenberechnung!$C$11*Kostenberechnung!$B$16,Kostenberechnung!$B$11*$F34^Kostenberechnung!$C$11))/100) -> 0.007449119 | M34: 500 | O34: 1000 | R34: agenitor 420 | Y34: 90 | Z34: 70
A35: 34 | B35: avus 500plus | ct80-B-0 | C35: 2G Energy AG | D35: BHKW-Modul, Erdgas, 600 kWel | E35: 628 | F35: 600 | G35: 3 | H35: 42.8 | I35: =IF(ISNUMBER(SEARCH("Brennstoffzelle",$R35)),Kostenberechnung!$B$17,Kostenberechnung!$B$5*IF($G35=14,Kostenberechnung!$B$10*$F35^Kostenberechnung!$C$10,IF($G35=25,Kostenberechnung!$B$9*$F35^Kostenberechnung!$C$9*Kostenberechnung!$B$15,Kostenberechnung!$B$9*$F35^Kostenberechnung!$C$9))) -> 464.26442 | J35: =4.545*1.31 -> 5.95395 | K35: =IF(ISNUMBER(SEARCH("Brennstoffzelle",$R35)),Kostenberechnung!$B$18/100,Kostenberechnung!$B$5*IF($G35=14,Kostenberechnung!$B$12*$F35^Kostenberechnung!$C$12,IF($G35=25,Kostenberechnung!$B$11*$F35^Kostenberechnung!$C$11*Kostenberechnung!$B$16,Kostenberechnung!$B$11*$F35^Kostenberechnung!$C$11))/100) -> 0.0082802223 | M35: 500 | O35: 1000 | R35: agenitor 412 | Y35: 90 | Z35: 70
A36: 35 | B36: avus 416plus | ct80-0 | C36: 2G Energy AG | D36: BHKW-Modul, Erdgas, 800 kWel | E36: 786 | F36: 800 | G36: 3 | H36: 43.4 | I36: =IF(ISNUMBER(SEARCH("Brennstoffzelle",$R36)),Kostenberechnung!$B$17,Kostenberechnung!$B$5*IF($G36=14,Kostenberechnung!$B$10*$F36^Kostenberechnung!$C$10,IF($G36=25,Kostenberechnung!$B$9*$F36^Kostenberechnung!$C$9*Kostenberechnung!$B$15,Kostenberechnung!$B$9*$F36^Kostenberechnung!$C$9))) -> 399.87311 | J36: =5.505*1.675 -> 9.220875 | K36: =IF(ISNUMBER(SEARCH("Brennstoffzelle",$R36)),Kostenberechnung!$B$18/100,Kostenberechnung!$B$5*IF($G36=14,Kostenberechnung!$B$12*$F36^Kostenberechnung!$C$12,IF($G36=25,Kostenberechnung!$B$11*$F36^Kostenberechnung!$C$11*Kostenberechnung!$B$16,Kostenberechnung!$B$11*$F36^Kostenberechnung!$C$11))/100) -> 0.0078307594 | M36: 500 | O36: 1000 | R36: agenitor 416 | Y36: 90 | Z36: 70

Sheet Kostenberechnung
A1: Kostenberechnung – Investition & Wartung (Interpolation, an Stichproben kalibriert)
A3: Modell: Potenzfunktion Wert = Preisfaktor × a × Pel^b | a, b an aktuelle Marktstichproben (2025/26) angepasst
A5: Preisfaktor (global, anpassbar) | B5: 1 | C5: 1,00 = Stichproben-kalibriertes Niveau 2025/26
A7: Modell-Koeffizienten (verwendet)
A8: Funktion | B8: a | C8: b | D8: Einheit | E8: Herkunft
A9: Investition Erdgas / Gas | B9: 12841.8 | C9: -0.519 | D9: €/kWel | E9: Fit an Stichproben, R²=0,93
A10: Investition Biogas | B10: 15648 | C10: -0.536 | D10: €/kWel | E10: ASUE (keine Biogas-Stichprobe)
A11: Wartung Erdgas / Gas | B11: 2.8642 | C11: -0.194 | D11: ct/kWhel | E11: Fit an Stichproben, R²=0,97
A12: Wartung Biogas | B12: 17.053 | C12: -0.478 | D12: ct/kWhel | E12: ASUE (keine Biogas-Stichprobe)
A14: Zuschläge / Sonderfälle
A15: H2-Aufschlag Investition (Faktor) | B15: 1.4
A16: H2-Aufschlag Wartung (Faktor) | B16: 1.3
A17: Brennstoffzelle Investition | B17: 30000 | C17: €/kWel
A18: Brennstoffzelle Wartung | B18: 3.5 | C18: ct/kWhel
A20: ASUE-Referenz 2011 (Basis 87/127 Anlagen): Invest Erdgas 9332,6·p^-0,461 | Biogas 15648·p^-0,536 | Wartung Erdgas 2,8046·p^-0,174 | Biogas 17,053·p^-0,478
A22: Interpolations-/Stützstellentabelle (aus Koeffizienten berechnet)
A23: Pel [kWel] | B23: Invest Erdgas [€/kWel] | C23: Invest Biogas [€/kWel] | D23: Wartung Erdgas [€/kWhel] | E23: Wartung Biogas [€/kWhel]
A24: 1 | B24: =$B$5*$B$9*A24^$C$9 -> 12841.8 | C24: =$B$5*$B$10*A24^$C$10 -> 15648 | D24: =$B$5*$B$11*A24^$C$11/100 -> 0.028642 | E24: =$B$5*$B$12*A24^$C$12/100 -> 0.17053
A25: 5 | B25: =$B$5*$B$9*A25^$C$9 -> 5570.0676 | C25: =$B$5*$B$10*A25^$C$10 -> 6604.0586 | D25: =$B$5*$B$11*A25^$C$11/100 -> 0.020960573 | E25: =$B$5*$B$12*A25^$C$12/100 -> 0.079012014
A26: 10 | B26: =$B$5*$B$9*A26^$C$9 -> 3887.1017 | C26: =$B$5*$B$10*A26^$C$10 -> 4554.6901 | D26: =$B$5*$B$11*A26^$C$11/100 -> 0.018323285 | E26: =$B$5*$B$12*A26^$C$12/100 -> 0.056728434
A27: 20 | B27: =$B$5*$B$9*A27^$C$9 -> 2712.6348 | C27: =$B$5*$B$10*A27^$C$10 -> 3141.2808 | D27: =$B$5*$B$11*A27^$C$11/100 -> 0.016017824 | E27: =$B$5*$B$12*A27^$C$12/100 -> 0.040729441
A28: 50 | B28: =$B$5*$B$9*A28^$C$9 -> 1686.0113 | C28: =$B$5*$B$10*A28^$C$10 -> 1922.2546 | D28: =$B$5*$B$11*A28^$C$11/100 -> 0.013409209 | E28: =$B$5*$B$12*A28^$C$12/100 -> 0.026284101
A29: 100 | B29: =$B$5*$B$9*A29^$C$9 -> 1176.592 | C29: =$B$5*$B$10*A29^$C$10 -> 1325.7415 | D29: =$B$5*$B$11*A29^$C$11/100 -> 0.011722044 | E29: =$B$5*$B$12*A29^$C$12/100 -> 0.018871255
A30: 160 | B30: =$B$5*$B$9*A30^$C$9 -> 921.9081 | C30: =$B$5*$B$10*A30^$C$10 -> 1030.506 | D30: =$B$5*$B$11*A30^$C$11/100 -> 0.0107005 | E30: =$B$5*$B$12*A30^$C$12/100 -> 0.015074102
A31: 250 | B31: =$B$5*$B$9*A31^$C$9 -> 731.2991 | C31: =$B$5*$B$10*A31^$C$10 -> 811.26547 | D31: =$B$5*$B$11*A31^$C$11/100 -> 0.0098130267 | E31: =$B$5*$B$12*A31^$C$12/100 -> 0.012178266
A32: 360 | B32: =$B$5*$B$9*A32^$C$9 -> 605.20834 | C32: =$B$5*$B$10*A32^$C$10 -> 667.23788 | D32: =$B$5*$B$11*A32^$C$11/100 -> 0.0091428302 | E32: =$B$5*$B$12*A32^$C$12/100 -> 0.010230296
A33: 500 | B33: =$B$5*$B$9*A33^$C$9 -> 510.34101 | C33: =$B$5*$B$10*A33^$C$10 -> 559.51395 | D33: =$B$5*$B$11*A33^$C$11/100 -> 0.0085783381 | E33: =$B$5*$B$12*A33^$C$12/100 -> 0.0087436574
A34: 750 | B34: =$B$5*$B$9*A34^$C$9 -> 413.4939 | C34: =$B$5*$B$10*A34^$C$10 -> 450.22126 | D34: =$B$5*$B$11*A34^$C$11/100 -> 0.0079294206 | E34: =$B$5*$B$12*A34^$C$12/100 -> 0.0072031342
A35: 1000 | B35: =$B$5*$B$9*A35^$C$9 -> 356.14422 | C35: =$B$5*$B$10*A35^$C$10 -> 385.88584 | D35: =$B$5*$B$11*A35^$C$11/100 -> 0.0074989998 | E35: =$B$5*$B$12*A35^$C$12/100 -> 0.0062777034
... A38: 2547 | B38: =$B$5*$B$9*A38^$C$9 -> 219.22843 | C38: =$B$5*$B$10*A38^$C$10 -> 233.79075 | D38: =$B$5*$B$11*A38^$C$11/100 -> 0.0062550923 | E38: =$B$5*$B$12*A38^$C$12/100 -> 0.0040153089
A40: Stichproben Investition (Erdgas) – Markt 2025/26
A41: Pel [kWel] | B41: Stichprobe [€/kWel] | C41: Modell [€/kWel] | D41: Abw. | E41: Quelle
A42: 1 | B42: 11000 | C42: =$B$5*$B$9*A42^$C$9 -> 12841.8 | D42: =C42/B42-1 -> 0.16743636 | E42: EFH-Stromheizung 7–15k €/kW o. Inst. (heizungsfinder)
A43: 2 | B43: 11000 | C43: =$B$5*$B$9*A43^$C$9 -> 8961.7192 | D43: =C43/B43-1 -> -0.18529825 | E43: Nano-BHKW 22k € / 2 kW (ihr-bhkw)
A44: 4 | B44: 7000 | C44: =$B$5*$B$9*A44^$C$9 -> 6253.984 | D44: =C44/B44-1 -> -0.10657371 | E44: Angebot 28k € / 4 kW (ihr-bhkw)
A45: 30 | B45: 1700 | C45: =$B$5*$B$9*A45^$C$9 -> 2197.8597 | D45: =C45/B45-1 -> 0.29285866 | E45: Erdgas 30 kW ~1.700 €/kW (heizungsfinder)
A46: 50 | B46: 3800 | C46: =$B$5*$B$9*A46^$C$9 -> 1686.0113 | D46: =C46/B46-1 -> -0.55631283 | E46: Sokratherm GG50 schlüsselfertig 190k € – Projekt (nicht im Fit)
A47: 250 | B47: 750 | C47: =$B$5*$B$9*A47^$C$9 -> 731.2991 | D47: =C47/B47-1 -> -0.024934537 | E47: Erdgas 250 kW ~180k € (heizungsfinder/ihr-bhkw)
A48: 500 | B48: 550 | C48: =$B$5*$B$9*A48^$C$9 -> 510.34101 | D48: =C48/B48-1 -> -0.072107253 | E48: Erdgas 500 kW 500–600 €/kW
A50: Stichproben Wartung/Vollwartung (Erdgas) – Markt 2025/26
...

Sheet Energieträger
A3: Energieträger | B3: Nummer
A4: Name | B4: ID
A5: Stadtgas | B5: 1
A6: Erdgas LL | B6: 2
A7: Erdgas E | B7: 3
A8: Flüssiggas (Propan) | B8: 4
A9: Flüssiggas (Butan) | B9: 5
A10: Heizöl S | B10: 6
A11: Heizöl M | B11: 7
A12: Heizöl L | B12: 8
A13: Heizöl EL | B13: 9
A14: Koks | B14: 10
A15: Kohle | B15: 11
A16: Holz | B16: 12
... A29: Wasserstoff | B29: 25

Sheet Legende
A1: Feld | B1: Einheit / Bedeutung | C1: Quelle
A2: Ptherm | B2: Nutzbare therm. Leistung bei 100% Last (kW) | C2: 2G Technical Specification
A3: Pel | B3: Elektrische Leistung bei 100% Last (kW) | C3: 2G Technical Specification
A4: Brennstoff | B4: Brennstoffart (Erdgas / Biogas 50% CH4 / Wasserstoff) | C4: 2G Technical Specification
A5: Wirkungsgrad | B5: Elektrischer Wirkungsgrad bei 100% Last (%) | C5: 2G Technical Specification
A6: Raumbedarf | B6: Modul-Grundflaeche = Laenge x Breite (m2) | C6: 2G Technical Specification, Kap. 8.1
A7: NOX | B7: NOx-Emission, mit Katalysator (mg/Nm3, 5% O2) | C7: 2G Technical Specification, Kap. 1.2
A8: CO | B8: CO-Emission, mit Katalysator (mg/Nm3, 5% O2) | C8: 2G Technical Specification, Kap. 1.2
A9: Motortyp | B9: Motortyp-Bezeichnung | C9: 2G Technical Specification, Kap. 1.3
A10: Grenzleistung | B10: ISO-Standardleistung mechanisch (kW) | C10: 2G Technical Specification, Kap. 1.3
A11: Vorlauf | B11: Heizwasser-Vorlauftemperatur max (degC) | C11: 2G Technical Specification, Kap. 3.1
A12: Ruecklauf | B12: Heizwasser-Ruecklauftemperatur max (degC) | C12: 2G Technical Specification, Kap. 3.1
... A17: Kosten_* | B17: Kostenpositionen - nicht im Datenblatt enthalten | C17: -
